Workbook

Sheet EF01
A1: TILLAGE
A2: Date | B2: Field | C2: Split | D2: Tractor | E2: Tool | F2: Depth | G2: Tillage Type
A3: 43919 | B3: HF 12 | C3: Whole Field | D3: Case IH puma | E3: brillion folding pulvi mulcher | F3: 2.00 " | G3: Minimum Till
A4: 43917.579 | B4: HF 12 | C4: Whole Field | D4: Case 290 | E4: Landoll | G4: Conventional
A5: 43594 | B5: HF 12 | C5: Whole Field | D5: John Deere 7810 | E5: 12 Row Rotary Hoe | F5: 1.00 " | G5: Conventional
A6: 43593.417 | B6: HF 12 | C6: Whole Field | D6: Case 290 | E6: Krause field cultivator | G6: Conventional
A7: 43265.528 | B7: HF 12 | C7: Whole Field | D7: Case 185 Puma | E7: 12 Row Crop Cultivator
A8: 43247.56 | B8: HF 12 | C8: Whole Field | D8: John Deere 7810 | E8: 12 Row Rotary Hoe
A9: 43235.304 | B9: HF 12 | C9: Whole Field | D9: Case 250 | E9: Krause field cultivator
A10: 43228.468 | B10: HF 12 | C10: Whole Field | D10: Case 290 | E10: 10-bottom Kverneland Plow | F10: 10.00 " | G10: Conventional
A12: PLANTING
A13: Date | B13: End Date | C13: Field | D13: Split | E13: Area | F13: Tool | G13: Crop | H13: Variety | I13: Population | J13: NPK Material | K13: Code | L13: LEFT BARE? | M13: Notes | N13: Perrenial Status | O13: Score | P13: Altered | Q13: Date Extension | R13: CODE | S13: DESCRIPTION | T13: RANK
A14: 43054.886 | B14: 43221 | C14: HF 12 | D14: Whole Field | E14: 26.48 | F14: Turbo Till & Turbo Seeder | G14: Rye(RYE) | H14: SHF Field Run - Rows | I14: 120 Lbs/Ac | J14: _____ | K14: CCF | O14: 6 | P14: N
A15: 43221 | B15: 43240 | C15: HF 12 | G15: Cover Crop | K15: CCF | O15: 3 | P15: Y
A16: 43240 | B16: 43247.547 | C16: HF 12 | D16: Whole Field | E16: 26.48 | F16: Kinze No Till Planter | G16: Corn, Field(FLDCRN) | H16: Organic Viking 035-99N 0 Bags | I16: 34000 /Ac | J16: 2015 Liquid Corn Blend (Fish, Humates, StressX, Compost Tea) 15.00 Gal | K16: WA | O16: 4 | P16: N
A17: 43247.547 | B17: 43250 | C17: HF 12 | D17: Whole Field | E17: 26.48 | F17: Kinze No Till Planter | G17: Corn, Field(FLDCRN) | H17: Viking 053-03UP 0 | I17: 34000 | J17: _____ | K17: WA | O17: 4 | P17: N
A18: 43250 | B18: 43400.802 | C18: HF 12 | D18: Whole Field | E18: 26.48 | F18: Kinze No Till Planter | G18: Corn, Field(FLDCRN) | I18: 34000 /Ac | J18: 2018 Liquid Corn Starter 15.00 Gal | K18: WA | O18: 4 | P18: N
A19: 43400.802 | B19: 43594.771 | C19: HF 12 | D19: Whole Field | E19: 26.48 | F19: Turbo Till & Turbo Seeder | G19: Rye(RYE) | H19: SHF Field Run 0 Bags | I19: 150 Lbs/Ac | J19: _____ | K19: CCF | O19: 6 | P19: N
A20: 43594.771 | B20: 43780.441 | C20: HF 12 | D20: Whole Field | E20: 26.48 | F20: Turbo Till & Turbo Seeder | G20: Soybeans (YSB) | H20: Viking 2219 0 | I20: 150 Lbs/Ac | J20: _____ | K20: WAL | O20: 7 | P20: N
A21: 43780.441 | B21: 43919 | C21: HF 12 | D21: Whole Field | E21: 26.48 | F21: Turbo Till & Turbo Seeder | G21: Rye(RYE) | I21: 120 Lbs/Ac | J21: _____ | K21: CCF | O21: 6 | P21: N
A22: 43919 | B22: 43938.338 | C22: HF 12 | D22: Whole Field | E22: 26.48 | F22: Turbo Till & Turbo Seeder | G22: Barley(BARL) | I22: 150 /Ac | J22: _____ | K22: SGS | O22: 5 | P22: N
A23: 43938.338 | B23: 44090.356 | C23: HF 12 | D23: Whole Field | E23: 26.48 | F23: Carovail Spreader Truck | G23: Cover Crop | H23: Brome, Fleet - Rows Orchard Grass, Otello - Rows Alfalfa, Viking 372HD - Units | I23: 11.50 Lbs/Ac | J23: _____ | K23: CCP | N23: B | O23: 1 | P23: N
A24: 44090.356 | B24: 44561 | C24: HF 12 | D24: Whole Field | E24: 26.48 | F24: JD 1590 Drill | G24: Grass (GRASS) | H24: orchard 0 | I24: 6 Lbs/Ac | J24: _____ | K24: CCP | O24: 1 | P24: N
A26: NPK
A27: Date | B27: Action | F27: Notes
A28: 43028 | B28: Fertilize | C28: Material | D28: rate
C29: Composted Poultry Litter | D29: 1.5 ton/ac
A30: 43084 | B30: Fertilize | C30: Material | D30: rate
C31: High Calcium Limestone (22%) | D31: 1 ton/ac
A32: 43222 | B32: Fertilize | C32: Material | D32: rate
C33: Composted poultry litter | D33: 1 ton/ac
A34: 43240 | B34: Fertilize | C34: Material | D34: rate
C35: Compost tea starter: barrel compost, compost tea catalyst, fish emulsion, humates, SeaCrop, Stress-X, Molasses | D35: 15 gal/ac
A37: HARVEST
A38: Date | B38: Field | C38: Split | D38: Area | E38: Hay type | F38: Crop | G38: % Moisture | H38: Yeild | I38: Unit | J38: Yeild-per-acre
A39: 43399 | B39: HF 12 | C39: Whole Field | D39: 26.48 | E39: _____ | F39: Corn, Field(FLDCRN) | G39: _____ | H39: 2421.4 | I39: Bu | J39: =H39/D39 -> 91.442598
A40: 43775 | B40: HF 12 | C40: Whole Field | D40: 26.48 | E40: _____ | F40: Soybeans (YSB) | G40: _____ | H40: 707.33 | I40: Bu | J40: =H40/D40 -> 26.711858
A41: 44021 | B41: HF 12 | C41: Whole Field | D41: 26.48 | E41: _____ | F41: Barley(BARL) | G41: _____ | H41: 1440.7 | I41: Bu | J41: =H41/D41 -> 54.4071
A42: 44352 | B42: HF 12 | D42: 26.48 | F42: Hay (alfalfa) | H42: =J42*D42 -> 26.48 | I42: ton | J42: 1
A43: 44418 | B43: HF 12 | D43: 26.48 | F43: Hay (alfalfa) | H43: =J43*D43 -> 26.48 | I43: ton | J43: 1

Sheet EF02
A1: Date | B1: Action | F1: Notes
A3: 2018
B4: Fertilize | C4: Material | D4: rate
A5: 43179 | C5: Potash | D5: 60 lbs/ac
B6: Tillage | C6: Implement | D6: Depth
A7: Late apr-erly may | C7: IH 875 disc ripper | D7: 9”
B8: Tillage | C8: Implement | D8: Depth
A9: Late apr-erly may | C9: Turbo till | D9: 2”
B10: Plant | C10: Crop | D10: Variety | E10: rate
A11: 43230 | C11: Corn | D11: Dekalb 49-94 | E11: 32000 SDS/AC
B12: Herbicide | C12: Material | D12: rate
A13: 5/12/18 (?) | C13: Instigate | D13: 6 oz/ac | F13: Pre-emergence
B14: Herbicide | C14: Material | D14: rate
A15: 5/12/18 (?) | C15: DuPont Cinch | D15: 48 oz/ac | F15: Pre-emergence
B16: Fertilize | C16: Material | D16: rate
A17: 6/27/18 (?) | C17: UAN | D17: 180 lbs/ac | F17: liquid
B18: Fertilize | C18: Material | D18: rate
A19: 6/28/18 (?) | C19: Phosphorus | D19: 20 lbs/ac
A20: 43377 | B20: Harvest | C20: Crop | D20: Yield
C21: Corn | D21: 194 bu/ac
A22: 43559 | B22: Fertilize | C22: Material | D22: rate
C23: Lime | D23: 2 tons/ac | F23: Confirm
A25: 2019
B27: Fertilize | C27: Material | D27: rate
A28: Early spring | C28: Chicken litter | D28: 1.5 t/ac
B30: Plant | C30: Crop | D30: Variety | E30: rate
A31: June | C31: soybeans | E31: 150,000 sds/ac
B33: Harvest | C33: Crop | D33: Yield | E33: Area
A34: October | C34: soybeans | D34: 56 bu/ac | E34: 53 ac
B36: Plant | C36: Crop | D36: Variety | E36: rate
A37: October (Post Harvest) | C37: Cereal Rye Cover | E37: ~120 lbs/ac
A39: 2020
B41: Tillage | C41: Implement | D41: Depth
A42: April | C42: Turbo-Till | D42: 4-5"
B44: Plant | C44: Crop | D44: Variety | E44: rate
A45: April | C45: Barley | E45: 100 lbs/ac
B47: Harvest | C47: Crop | D47: Yield | E47: Area
A48: July | C48: Barley | D48: 43 bu/ac | E48: 42.5 ac
B50: Tillage | C50: Implement | D50: Depth
A51: July | C51: Turbo Till | D51: 4-5"
...

Sheet EF03
A2: 2018
A6: DATE | B6: EVENT | C6: Grazing Days? | D6: FIELD | E6: Yield (lbs DM) | F6: DETAILS
A7: 43237 | B7: CATTLE BEGIN 1st GRAZING | C7: duration of grazing period and total acres grazed? 21 days? | D7: S1-2 | E7: =((900*0.03)*30*21) -> 17010 | F7: 30 head (avg 900lbs)/ acre/ day
A8: 43258 | B8: CATTLE BEGIN 2ND GRAZING | D8: S1-2 | F8: 30 head (avg 940lbs)/ acre/ day
A9: 43278 | B9: CATTLE END 2ND GRAZING | C9: assuming 20 days of grazing across s1&s2? | D9: S1-2 | E9: =(940*0.03)*30*20 -> 16920 | F9: 30 head (avg 980lbs)/ acre/ day
A10: 43261 | B10: MOW | D10: S3 | F10: 6 ACRES
A11: 43262 | B11: BALE AND WRAP (BALEAGE) | D11: S3 | E11: =1600*0.5*28 -> 22400 | F11: 28 LARGE BALES (APPROX. 1600LBS EACH)
A12: 43265 | B12: MOW | D12: S3-4 | F12: 16 ACRES
A13: 43269 | B13: BALE (DRY HAY) | D13: S3-4 | E13: =58*700 -> 40600 | F13: 58 LARGE ROUND BALES (APPROX 700LBS EACH)
A14: 43269 | B14: BALE (DRY HAY) | D14: S3-4 | E14: =650*45 -> 29250 | F14: 650 SMALL SQURE BALES (AVG 45 LBS EACH)
A15: 43333 | B15: SPRAY | D15: S1-4 | F15: APLLIED HORN SILICA PREP 501 AT 5 GAL/ACRE
A16: 43336 | B16: MOW | D16: S3-4 | F16: 23 ACRES
A17: 43340 | B17: BALE (DRY HAY) | D17: S3-4 | E17: =1100*55 -> 60500 | F17: 1100 SMALL SQUARE BALES (AVG 55 LBS)
A18: 43397 | B18: CATTLE BEGIN GRAZING | C18: how many days? | D18: S1 | E18: =((700*0.03)*26*20) -> 10920 | F18: 26 head (avg700lbs)/0.75 acre/ day
D20: Total Hay Yield | E20: =SUM(E17,E14,E13,E11) -> 152750 | F20: lbs DM | G20: =E20/2000 -> 76.375 | H20: tons (uUS short) DM
D21: Total Grazing Yield | E21: =SUM(E7,E9,E18) -> 44850 | F21: lbs DM | G21: =E21/2000 -> 22.425 | H21: tons (uUS short) DM
D22: Total Harvested Yield | E22: =E21+E20 -> 197600 | F22: lbs DM | G22: =E22/2000 -> 98.8 | H22: tons (uUS short) DM
A25: 2019
C26: Churchtown Dairy Hudson Carbon Log 2019 | F26: Research Station is located in field S2
B28: Date | C28: Action | E28: Machine | F28: Implement | G28: Field | H28: Yield | I28: Notes
B31: 5/1-5/14 | C31: Grazing | E31: 40 beef (@600 lbs) | G31: S2,S3 | H31: =(600*0.03)*40*14 -> 10080 | I31: Note: Beef alternated between S3 & S2 each day, proceeding north to south
B32: 5/15-5/19 | C32: Grazing | E32: 40 beef (@600 lbs) | G32: S4 | H32: =(600*0.03)*40*5 -> 3600
B33: 6/8-6/19 | C33: Grazing | E33: 40 beef (@600 lbs) | G33: S4 | H33: =(600*0.03)*40*12 -> 8640
B34: 5/20-6/4 | C34: Grazing | E34: 40 beef (@600 lbs) | G34: S2,S3 | H34: =(600*0.03)*40*16 -> 11520
B35: 6/5 - 6/9 | C35: Grazing | E35: 40 beef (@600 lbs) | G35: S4 | H35: =(600*0.03)*40*5 -> 3600
B36: 6/10-6/23 | C36: Grazing | E36: 40 beef (@600 lbs) | G36: S2,S3 | H36: =(600*0.03)*40*14 -> 10080
B37: 6/24- 6/30 | C37: Grazing | E37: 40 beef (@600 lbs) | G37: S4 | H37: =(600*0.03)*40*7 -> 5040
B38: 7/1 - 7/15 | C38: Grazing | E38: 40 beef (@600 lbs) | G38: S2,3 | H38: =(600*0.03)*40*15 -> 10800
B39: 8/20-8/30 | C39: Grazing | E39: 30 Dairy + calves (@ 1250 lbs) | G39: S1 | H39: =(1250*0.03)*30*11 -> 12375
B40: 8/31-9/9 | C40: Grazing | E40: 31 Dairy + calves (@ 1250 lbs) | G40: S2 | H40: =(1250*0.03)*30*10 -> 11250 | I40: South of Research Station
B41: 10/18-11/5 | C41: Grazing | E41: 40 beef (@600 lbs) | G41: S2 | H41: =(600*0.03)*40*19 -> 13680
B42: 43616 | C42: mowed | E42: 110 HP tractor | G42: S1
B43: 43617 | C43: baled | E43: 110 HP tractor | G43: S1 | I43: how many bales?
B44: 43619 | C44: mowed | E44: 110 HP tractor | G44: S1
B45: 43620 | C45: baled | E45: 110 HP tractor | G45: S1 | I45: how many bales?
B46: 43622 | C46: mowed | E46: 110 HP tractor | G46: S1
B47: 43623 | C47: baled | E47: 110 HP tractor | G47: S1 | I47: how many bales?
B48: 43627 | C48: mowed | E48: 110 HP tractor | G48: S2 2nd Half of Field
B49: 43628 | C49: baled | E49: 110 HP tractor | G49: S2 2nd Half of Field | I49: how many bales?
B50: 43714 | C50: spread compost | E50: 89 HP tractor | G50: S3, S4
...

Sheet Hay Yields by Subfield (EF03)
A1: Harvest Comparison for South-Fields 2018-2024
B3: 2018 | D3: 2019 | F3: 2020 | H3: 2021 | J3: 2022 | L3: 2023 | N3: 2024 | O3: (equivalent + 25%)
A5: S 1 | B5: 30 beef head grazing | D5: cut and baled 6/7 | F5: 31 RB | H5: 66 RB | J5: 21 RB | L5: 67 RB | N5: 41 RB (51 RB)
B6: from 5/17 | D6: then 30 dairy graze | F6: 220smsq | H6: 540smsq | J6: 540smsq | L6: 150smsq | N6: 350smsq
B7: until 6/27 | D7: from 8/20 to 8/30 | F7: =(31*525)+(220*45) -> 26175 | G7: lbs dm | H7: =(66*B27)+(540*B28) -> 58950 | I7: lbs dm | J7: =(21*B27)+(540*B28) -> 35325 | K7: lbs dm | L7: =(67*B27)+(150*B28) -> 41925 | M7: lbs dm | N7: =(51*B27)+(350*B28) -> 42525 | O7: lbs dm
A8: S 2 | B8: and on S1 again | D8: 30 dairy graze from | F8: 24 RB | H8: 20 RB | J8: 21 RB | L8: 67 RB | N8: 48 RB (60 RB)
B9: from 10/24 | D9: 8/31 to 9/9 40 beef | F9: 220smsq | H9: 1840smsq | J9: 524smsq | L9: 150smsq | N9: 210smsq
D10: from 10/18 to 11/5 | F10: =(24*525)+(220*45) -> 22500 | G10: lbs dm | H10: =(20*B27)+(1840*B28) -> 93300 | I10: lbs dm | J10: =(21*B27)+(524*B28) -> 34605 | K10: lbs dm | L10: =(67*B27)+(150*B28) -> 41925 | M10: lbs dm | N10: =(60*B27)+(210*B28) -> 40950 | O10: lbs dm
A11: S 3 | B11: 61 RB | F11: 27 RB | H11: 94 RB | J11: 55 RB | L11: 45 RB | N11: 28 RB (35 RB)
B12: 1300smsq | D12: 40 beef graze S2, S3 | F12: =27*B27 -> 14175 | G12: lbs dm | H12: =94*B27 -> 49350 | I12: lbs dm | J12: =55*B27 -> 28875 | K12: lbs dm | L12: 600smsq | N12: 610smsq
B13: =(61*525)+(1300*45) -> 90525 | C13: lbs dm | D13: and S4 from 5/1 | L13: =(45*B27)+(600*B28) -> 50625 | M13: lbs dm | N13: =(35*B27)+(610*B28) -> 45825 | O13: lbs dm
A14: S 4 | B14: 25 RB | D14: until 7/15 | F14: 12 RB | H14: 18 RB | J14: 25 RB | L14: 39 RB | N14: 25 RB (31 RB)
B15: 450smsq | F15: 85smsq | H15: 90smsq | J15: =25*B27 -> 13125 | K15: lbs dm | L15: 150smsq | N15: =(31*B27) -> 16275 | O15: lbs dm
B16: =(25*B27)+(450*B28) -> 33375 | C16: lbs dm | F16: =(12*B27)+(85*B28) -> 10125 | G16: lbs dm | H16: =(18*B27)+(90*45) -> 13500 | I16: lbs dm | L16: =(39*B27)+(150*B28) -> 27225 | M16: lbs dm
A19: Total | B19: 86 RB + 1750smsq | F19: 94 RB + 525smsq | H19: 198 RB + 2470smsq | J19: 122 RB + 1014smsq | L19: 218 RB + 1050smsq | N19: 177 RB + 1170smsq
A22: Total Hay Yield in lbs DM | B22: =(86*B27)+(1750*B28) -> 123900 | F22: =(94*B27)+(525*B28) -> 72975 | H22: =(198*B27)+(2470*B28) -> 215100 | J22: =(122*B27)+(1014*B28) -> 109680 | L22: =(218*B27)+(1050*B28) -> 161700 | N22: =(177*B27)+(1170*B28) -> 145575
A26: standard bale weights in lbs DM
A27: 4x4 round bale | B27: 525
A28: small square | B28: 45
A32: Sub-Field Acreage
A33: S-1 | B33: 15.2
A34: S-2 | B34: 15.3
A35: S-3 | B35: 15.5
A36: S-4 | B36: 6
