Workbook

Sheet Data Fields
A1: Data Parameter | B1: Format - or example data | C1: Unit | D1: Data Type | E1: Process Field | F1: Calculation (if necessary) | G1: Notes
A2: Sample Site | B2: C-[X] | C2: unitless | D2: Select 1 of 12 | E2: Bulk Density
A3: Sample ID | B3: X15-46-[CX] | C3: unitless | D3: User Entry | E3: Bulk Density | G3: Naming Conversion: JulianDate.SampleSite (This particular sample is named differently because it is an older sample taken before the current naming conversion)
A4: Initial Soil Wet Weight (entire core) | B4: 715 | C4: grams | D4: User Entry | E4: Bulk Density | G4: Three cores are taken (from the N, E, and W) of a "C" site for each "sample ID" record. Users will select N, E, or W each of the three measurments
A5: Wet Weight (sample) | B5: 4.14 | C5: grams | D5: User Entry | E5: Bulk Density | G5: Users will select N, E, or W each of the three measurments
A6: Oven Dry Weight (sample) | B6: 3.4 | C6: grams | D6: User Entry | E6: Bulk Density | G6: Users will select N, E, or W each of the three measurments
A7: Percent Moisture | B7: 17.874396 | C7: % | D7: Calculated | E7: Bulk Density | F7: ([[wet wt] - [dry wt]]/[wet wt]]* 100) | G7: Users will select N, E, or W each of the three measurments
A8: Calculated Dried Weight | B8: 587.19807 | C8: grams | D8: Calculated | E8: Bulk Density | F8: [Initial Soil Wet Weight]-[Percent Moisture/100)*[Initial Soil Wet Weight] | G8: Users will select N, E, or W each of the three measurments
A9: Bulk Density | B9: 1.1866626 | C9: g/cm3 | D9: Calculated | E9: Bulk Density | F9: [Calculated Dried Weight]/[Core Volume] | G9: Users will select N, E, or W each of the three measurments
A10: Mean Bulk Density | B10: 1.1438455 | C10: g/cm3 | D10: Calculated | E10: Bulk Density | F10: avg(Bulk Density[N], Bulk Density[E], Bulk Density[W])
A11: Core Type | B11: C1 | D11: Select C1-C5 | E11: Soil Core | G11: Users Select C1, C2, C3, C4, C5, Needs to be a way to override if user pulls a "short core"
A12: Core Radius | B12: 3.889375 | C12: cm | D12: Constant | E12: Soil Core | G12: This is the core radius for all cores taken prior to September 2019. Starting September 2019 the core radius is 3.81cm
A13: Core Height | B13: 10 | C13: cm | D13: Lookup | E13: Soil Core | G13: C1-C5 pertains to a core height
A14: Core Volume | B14: 475.23619 | C14: cm3 | D14: Constant | E14: Soil Core | G14: Core height varies depending if it is C1-C5
A15: Wt Silt | B15: 8.27 | C15: grams | D15: User Entry | E15: Elutriation | G15: Elutriation is done in 3 rounds, users will need to associate a weight measurement with a round
A16: Wt Clay | B16: 1.96 | C16: grams | D16: User Entry | E16: Elutriation | G16: Elutriation is done in 3 rounds, users will need to associate a weight measurement with a round
A17: Total Wt | B17: =B16+B15 -> 10.23 | C17: grams | D17: Calculated | E17: Elutriation | G17: Elutriation is done in 3 rounds, users will need to associate a weight measurement with a round
A18: Silt (%) | B18: 80.840665 | C18: % | D18: Calculated | E18: Elutriation | F18: wt silt/Total wt *100% | G18: Elutriation is done in 3 rounds, users will need to associate a % measurement with a round
A19: Clay (%) | B19: 19.159335 | C19: % | D19: Calculated | E19: Elutriation | F19: wt clay/Total wt *100% | G19: Elutriation is done in 3 rounds, users will need to associate a % measurement with a round
A20: Mean Silt (%) | B20: 81.109241 | C20: % | D20: Calculated | E20: Elutriation | F20: avg(Round1 silt%, Round 2 silt%, Round 3 silt%)
A21: Mean Clay (%) | B21: 18.890759 | C21: % | D21: Calculated | E21: Elutriation | F21: avg(Round1clay%, Round 2 clay%, Round3clay%)
A22: Weight #10 | B22: 19.64 | C22: grams | D22: User Entry | E22: Wet Sieve
A23: Weight #18 | B23: 11.23 | C23: grams | D23: User Entry | E23: Wet Sieve
A24: Weight #35 | B24: 7.32 | C24: grams | D24: User Entry | E24: Wet Sieve
A25: Weight #60 | B25: 7.43 | C25: grams | D25: User Entry | E25: Wet Sieve
A26: Weight #120 | B26: 9.89 | C26: grams | D26: User Entry | E26: Wet Sieve
A27: Weight #200 | B27: 9.6 | C27: grams | D27: User Entry | E27: Wet Sieve
A28: Weight #230 | B28: 3.57 | C28: grams | D28: User Entry | E28: Wet Sieve
A29: Weight Pan Sample | B29: 241.02 | C29: grams | D29: User Entry | E29: Wet Sieve
A30: Sum (Total Wet Sieve) | B30: =SUM(B22:B29) -> 309.7 | C30: grams | D30: Calculated | E30: Wet Sieve | F30: sum(Wt#10,#18…Pan Sample)
A31: Percent #10 | B31: =B22/$B$30*100 -> 6.3416209 | C31: % | D31: Calculated | E31: Wet Sieve | F31: Weight#10/Sum Total Wet Sieve*100
A32: Percent #18 | B32: =B23/$B$30*100 -> 3.6260898 | C32: % | D32: Calculated | E32: Wet Sieve | F32: Weight#18/Sum Total Wet Sieve*100
A33: Percent #35 | B33: =B24/$B$30*100 -> 2.3635777 | C33: % | D33: Calculated | E33: Wet Sieve | F33: Weight#35/Sum Total Wet Sieve*100
A34: Percent #60 | B34: =B25/$B$30*100 -> 2.3990959 | C34: % | D34: Calculated | E34: Wet Sieve | F34: Weight#60/Sum Total Wet Sieve*100
A35: Percent #120 | B35: =B26/$B$30*100 -> 3.193413 | C35: % | D35: Calculated | E35: Wet Sieve | F35: Weight#120/Sum Total Wet Sieve*100
A36: Percent #200 | B36: =B27/$B$30*100 -> 3.099774 | C36: % | D36: Calculated | E36: Wet Sieve | F36: Weight#200/Sum Total Wet Sieve*100
A37: Percent #230 | B37: =B28/$B$30*100 -> 1.1527284 | C37: % | D37: Calculated | E37: Wet Sieve | F37: Weight#230/Sum Total Wet Sieve*100
A38: Percent Pan | B38: =B29/$B$30*100 -> 77.8237 | C38: % | D38: Calculated | E38: Wet Sieve | F38: Wt. Pan Sample/Sum total Wet Sieve*100
A39: Pebbles | B39: =B31 -> 6.3416209 | C39: % | D39: Calculated | E39: Wet Sieve | F39: = Percent #10
A40: Very Coarse Sand | B40: =B32 -> 3.6260898 | C40: % | D40: Calculated | E40: Wet Sieve | F40: = Percent #18
...

Sheet Samples
A1: sample_id | B1: sample_date | C1: csite
A2: X11.1 | B2: 42160 | C2: CSITE 02
A3: X11.2 | B3: 42163 | C3: CSITE 11
A4: X11.3 | B4: 42165 | C4: CSITE 09
A5: X11.4 | B5: 42166 | C5: CSITE 01
A6: X11.5 | B6: 42166 | C6: CSITE 03
A7: X11.6 | B7: 42167 | C7: CSITE 10
A8: X11.7 | B8: 42174 | C8: CSITE 05
A9: X11.9 | B9: 42175 | C9: CSITE 06
A10: X11.10 | B10: 42178 | C10: CSITE 04
A11: X11.11 | B11: 42179 | C11: CSITE 12
A12: X11.12 | B12: 42179 | C12: CSITE 08
A13: X11.13 | B13: 42180 | C13: CSITE 07
... A151: 20107.EF02 | B151: 43937 | C151: EF02

Sheet Sample ID by Horizon
A1: Current Horizon ID | B1: Sample Date | C1: Site
A2: X11.1.H1 | B2: 42160 | C2: =VLOOKUP(LEFT(A2,LEN(A2)-3),Samples!$A$1:$C$151,3,FALSE) -> CSITE 02
A3: X11.2.H1 | B3: 42163 | C3: =VLOOKUP(LEFT(A3,LEN(A3)-3),Samples!$A$1:$C$151,3,FALSE) -> CSITE 11
A4: X11.3.H1 | B4: 42165 | C4: =VLOOKUP(LEFT(A4,LEN(A4)-3),Samples!$A$1:$C$151,3,FALSE) -> CSITE 09
A5: X11.4.H1 | B5: 42166 | C5: =VLOOKUP(LEFT(A5,LEN(A5)-3),Samples!$A$1:$C$151,3,FALSE) -> CSITE 01
A6: X11.5.H1 | B6: 42166 | C6: =VLOOKUP(LEFT(A6,LEN(A6)-3),Samples!$A$1:$C$151,3,FALSE) -> CSITE 03
A7: X11.6.H1 | B7: 42167 | C7: =VLOOKUP(LEFT(A7,LEN(A7)-3),Samples!$A$1:$C$151,3,FALSE) -> CSITE 10
A8: X11.7.H1 | B8: 42174 | C8: =VLOOKUP(LEFT(A8,LEN(A8)-3),Samples!$A$1:$C$151,3,FALSE) -> CSITE 05
A9: X11.9.H1 | B9: 42175 | C9: =VLOOKUP(LEFT(A9,LEN(A9)-3),Samples!$A$1:$C$151,3,FALSE) -> CSITE 06
A10: X11.10.H1 | B10: 42178 | C10: =VLOOKUP(LEFT(A10,LEN(A10)-3),Samples!$A$1:$C$151,3,FALSE) -> CSITE 04
A11: X11.12.H1 | B11: 42179 | C11: =VLOOKUP(LEFT(A11,LEN(A11)-3),Samples!$A$1:$C$151,3,FALSE) -> CSITE 08
A12: X11.11.H1 | B12: 42179 | C12: =VLOOKUP(LEFT(A12,LEN(A12)-3),Samples!$A$1:$C$151,3,FALSE) -> CSITE 12
A13: X11.13.H1 | B13: 42180 | C13: =VLOOKUP(LEFT(A13,LEN(A13)-3),Samples!$A$1:$C$151,3,FALSE) -> CSITE 07
... A538: 20107.EF02.C5 | B538: 43937 | C538: =VLOOKUP(LEFT(A538,LEN(A538)-3),Samples!$A$1:$C$151,3,FALSE) -> EF02
A539: 20326.CS01.S1 | B539: 44156 | C539: CSITE 01
A540: 20326.CS01.S2 | B540: 44156 | C540: CSITE 01
A541: 20326.CS01.S3 | B541: 44156 | C541: CSITE 01
A542: 20326.CS01.S4 | B542: 44156 | C542: CSITE 01
A543: 20326.CS01.S5 | B543: 44156 | C543: CSITE 01
A544: 20326.CS01.S6 | B544: 44156 | C544: CSITE 01
A545: 20326.CS01.S7 | B545: 44156 | C545: CSITE 01
A546: 20326.CS01.S8 | B546: 44156 | C546: CSITE 01
A547: 20326.CS01.S9 | B547: 44156 | C547: CSITE 01
A548: 20326.CS01.S10 | B548: 44156 | C548: CSITE 01
A549: 20326.CS01.S11 | B549: 44156 | C549: CSITE 01
A550: 20326.CS01.S12 | B550: 44156 | C550: CSITE 01
... A867: 18202.IES4.C5 | B867: 43302 | C867: IES4

Sheet Sites
A1: csite | B1: field_name | C1: soil_group | D1: texture
A2: CSITE1 | B2: MC 1 | C2: Knickerbocker | D2: Fine sandy loam
A3: CSITE2 | B3: MC 9 | C3: Niagara | D3: Silt loam
A4: CSITE3 | B4: MC 6 | C4: Niagara | D4: Silt loam
A5: CSITE4 | B5: HM 13 | C5: Hoosic | D5: Gravelly sandy loam
A6: CSITE5 | B6: MS 8 | C6: Collamer | D6: Silt loam
A7: CSITE6 | B7: CP 5B | C7: Collamer | D7: Silt loam
A8: CSITE7 | B8: CP 6C | C8: Collamer | D8: Silt loam
A9: CSITE8 | B9: HF 2A | C9: Knickerbocker | D9: Fine sandy loam
A10: CSITE9 | B10: RBD 3 | C10: Nassau | D10: Channery silt loam
A11: CSITE10 | B11: RBD 2 | C11: Blasdell | D11: Channery loam
A12: CSITE12 | B12: WA 5B | C12: Hoosic | D12: Gravelly sandy loam
... A40: NT2 | B40: BBC | C40: Collamer | D40: Silt Loam

Sheet Bulk Density
A1: Date | B1: CSite | C1: Sample_ID | D1: Sample Core ID (Shared Identifier) | E1: Core Direction | F1: Initial Soil Wet Weight (Entire Core) | G1: Wet Weight (sample) | H1: Oven Dry Weight (sample) | I1: Percent Moisture | J1: Calculated Dried Weight | K1: Core Radius | L1: Core Height | M1: Core Volume | N1: Bulk Density | O1: mean bulk density pantheon formula | P1: volume of soil pantheon formula | Q1: kg soil/ha pantheon formula
A2: =VLOOKUP(D2,'Sample ID by Horizon'!A:B,2,FALSE) -> 42160 | B2: =VLOOKUP(C2,Samples!A:C,3,FALSE) -> CSITE 02 | C2: =LEFT(D2,LEN(D2)-3) -> X11.1 | D2: X11.1.H1 | K2: 3.6 | L2: 15 | M2: =L2*PI()*K2^2 -> 610.72561 | O2: 2.4593696 | P2: =SUMIF(D:D,D2,L:L)/COUNTIF(D:D,D2)*100 -> 1500 | Q2: =O2*P2*1000 -> 3689054.4
A3: =VLOOKUP(D3,'Sample ID by Horizon'!A:B,2,FALSE) -> 42163 | B3: =VLOOKUP(C3,Samples!A:C,3,FALSE) -> CSITE 11 | C3: =LEFT(D3,LEN(D3)-3) -> X11.2 | D3: X11.2.H1 | K3: 3.6 | L3: 15 | M3: =L3*PI()*K3^2 -> 610.72561 | O3: 2.0688505 | P3: =SUMIF(D:D,D3,L:L)/COUNTIF(D:D,D3)*100 -> 1500 | Q3: =O3*P3*1000 -> 3103275.8
A4: =VLOOKUP(D4,'Sample ID by Horizon'!A:B,2,FALSE) -> 42165 | B4: =VLOOKUP(C4,Samples!A:C,3,FALSE) -> CSITE 09 | C4: =LEFT(D4,LEN(D4)-3) -> X11.3 | D4: X11.3.H1 | K4: 3.6 | L4: 15 | M4: =L4*PI()*K4^2 -> 610.72561 | O4: 1.7945866 | P4: =SUMIF(D:D,D4,L:L)/COUNTIF(D:D,D4)*100 -> 1500 | Q4: =O4*P4*1000 -> 2691879.9
A5: =VLOOKUP(D5,'Sample ID by Horizon'!A:B,2,FALSE) -> 42166 | B5: =VLOOKUP(C5,Samples!A:C,3,FALSE) -> CSITE 01 | C5: =LEFT(D5,LEN(D5)-3) -> X11.4 | D5: X11.4.H1 | K5: 3.6 | L5: 15 | M5: =L5*PI()*K5^2 -> 610.72561 | O5: 2.1580886 | P5: =SUMIF(D:D,D5,L:L)/COUNTIF(D:D,D5)*100 -> 1500 | Q5: =O5*P5*1000 -> 3237132.9
A6: =VLOOKUP(D6,'Sample ID by Horizon'!A:B,2,FALSE) -> 42166 | B6: =VLOOKUP(C6,Samples!A:C,3,FALSE) -> CSITE 03 | C6: =LEFT(D6,LEN(D6)-3) -> X11.5 | D6: X11.5.H1 | K6: 3.6 | L6: 15 | M6: =L6*PI()*K6^2 -> 610.72561 | O6: 2.2096666 | P6: =SUMIF(D:D,D6,L:L)/COUNTIF(D:D,D6)*100 -> 1500 | Q6: =O6*P6*1000 -> 3314499.9
A7: =VLOOKUP(D7,'Sample ID by Horizon'!A:B,2,FALSE) -> 42167 | B7: =VLOOKUP(C7,Samples!A:C,3,FALSE) -> CSITE 10 | C7: =LEFT(D7,LEN(D7)-3) -> X11.6 | D7: X11.6.H1 | K7: 3.6 | L7: 15 | M7: =L7*PI()*K7^2 -> 610.72561 | O7: 2.3120039 | P7: =SUMIF(D:D,D7,L:L)/COUNTIF(D:D,D7)*100 -> 1500 | Q7: =O7*P7*1000 -> 3468005.9
A8: =VLOOKUP(D8,'Sample ID by Horizon'!A:B,2,FALSE) -> 42174 | B8: =VLOOKUP(C8,Samples!A:C,3,FALSE) -> CSITE 05 | C8: =LEFT(D8,LEN(D8)-3) -> X11.7 | D8: X11.7.H1 | K8: 3.6 | L8: 15 | M8: =L8*PI()*K8^2 -> 610.72561 | O8: 2.2137601 | P8: =SUMIF(D:D,D8,L:L)/COUNTIF(D:D,D8)*100 -> 1500 | Q8: =O8*P8*1000 -> 3320640.2
A9: =VLOOKUP(D9,'Sample ID by Horizon'!A:B,2,FALSE) -> 42175 | B9: =VLOOKUP(C9,Samples!A:C,3,FALSE) -> CSITE 06 | C9: =LEFT(D9,LEN(D9)-3) -> X11.9 | D9: X11.9.H1 | K9: 3.6 | L9: 15 | M9: =L9*PI()*K9^2 -> 610.72561 | O9: 1.9566889 | P9: =SUMIF(D:D,D9,L:L)/COUNTIF(D:D,D9)*100 -> 1500 | Q9: =O9*P9*1000 -> 2935033.3
A10: =VLOOKUP(D10,'Sample ID by Horizon'!A:B,2,FALSE) -> 42178 | B10: =VLOOKUP(C10,Samples!A:C,3,FALSE) -> CSITE 04 | C10: =LEFT(D10,LEN(D10)-3) -> X11.10 | D10: X11.10.H1 | K10: 3.6 | L10: 15 | M10: =L10*PI()*K10^2 -> 610.72561 | O10: 2.2964486 | P10: =SUMIF(D:D,D10,L:L)/COUNTIF(D:D,D10)*100 -> 1500 | Q10: =O10*P10*1000 -> 3444673
A11: =VLOOKUP(D11,'Sample ID by Horizon'!A:B,2,FALSE) -> 42179 | B11: =VLOOKUP(C11,Samples!A:C,3,FALSE) -> CSITE 08 | C11: =LEFT(D11,LEN(D11)-3) -> X11.12 | D11: X11.12.H1 | K11: 3.6 | L11: 15 | M11: =L11*PI()*K11^2 -> 610.72561 | O11: 2.2530576 | P11: =SUMIF(D:D,D11,L:L)/COUNTIF(D:D,D11)*100 -> 1500 | Q11: =O11*P11*1000 -> 3379586.4
A12: =VLOOKUP(D12,'Sample ID by Horizon'!A:B,2,FALSE) -> 42179 | B12: =VLOOKUP(C12,Samples!A:C,3,FALSE) -> CSITE 12 | C12: =LEFT(D12,LEN(D12)-3) -> X11.11 | D12: X11.11.H1 | K12: 3.6 | L12: 15 | M12: =L12*PI()*K12^2 -> 610.72561 | O12: 2.677962 | P12: =SUMIF(D:D,D12,L:L)/COUNTIF(D:D,D12)*100 -> 1500 | Q12: =O12*P12*1000 -> 4016943
A13: =VLOOKUP(D13,'Sample ID by Horizon'!A:B,2,FALSE) -> 42180 | B13: =VLOOKUP(C13,Samples!A:C,3,FALSE) -> CSITE 07 | C13: =LEFT(D13,LEN(D13)-3) -> X11.13 | D13: X11.13.H1 | K13: 3.6 | L13: 15 | M13: =L13*PI()*K13^2 -> 610.72561 | O13: 2.2841682 | P13: =SUMIF(D:D,D13,L:L)/COUNTIF(D:D,D13)*100 -> 1500 | Q13: =O13*P13*1000 -> 3426252.2
... A26: =VLOOKUP(D26,'Sample ID by Horizon'!A:B,2,FALSE) -> 42234 | B26: =VLOOKUP(C26,Samples!A:C,3,FALSE) -> CSITE 01 | C26: =LEFT(D26,LEN(D26)-3) -> X11.46 | D26: X11.46.H1 | K26: 3.6 | L26: 15 | M26: =L26*PI()*K26^2 -> 610.72561 | O26: 2.1580886 | P26: =SUMIF(D:D,D26,L:L)/COUNTIF(D:D,D26)*100 -> 1500 | Q26: =O26*P26*1000 -> 3237132.9
A27: =VLOOKUP(D27,'Sample ID by Horizon'!A:B,2,FALSE) -> 42234 | B27: =VLOOKUP(C27,Samples!A:C,3,FALSE) -> CSITE 01 | C27: =LEFT(D27,LEN(D27)-3) -> X11.46 | D27: X11.46.H2 | J27: 854 | K27: 3.6 | L27: 15 | M27: =L27*PI()*K27^2 -> 610.72561 | N27: =J27/M27 -> 1.3983366 | O27: =SUMIF(D:D,D27,N:N)/COUNTIF(D:D,D27) -> 1.3983366 | P27: =SUMIF(D:D,D27,L:L)/COUNTIF(D:D,D27)*100 -> 1500 | Q27: =O27*P27*1000 -> 2097505
A28: =VLOOKUP(D28,'Sample ID by Horizon'!A:B,2,FALSE) -> 42234 | B28: =VLOOKUP(C28,Samples!A:C,3,FALSE) -> CSITE 02 | C28: =LEFT(D28,LEN(D28)-3) -> X11.47 | D28: X11.47.H1 | K28: 3.6 | L28: 15 | M28: =L28*PI()*K28^2 -> 610.72561 | O28: 2.4593696 | P28: =SUMIF(D:D,D28,L:L)/COUNTIF(D:D,D28)*100 -> 1500 | Q28: =O28*P28*1000 -> 3689054.4
A29: =VLOOKUP(D29,'Sample ID by Horizon'!A:B,2,FALSE) -> 42234 | B29: =VLOOKUP(C29,Samples!A:C,3,FALSE) -> CSITE 02 | C29: =LEFT(D29,LEN(D29)-3) -> X11.47 | D29: X11.47.H2 | J29: 849 | K29: 3.6 | L29: 15 | M29: =L29*PI()*K29^2 -> 610.72561 | N29: =J29/M29 -> 1.3901497 | O29: =SUMIF(D:D,D29,N:N)/COUNTIF(D:D,D29) -> 1.3901497 | P29: =SUMIF(D:D,D29,L:L)/COUNTIF(D:D,D29)*100 -> 1500 | Q29: =O29*P29*1000 -> 2085224.5
A30: =VLOOKUP(D30,'Sample ID by Horizon'!A:B,2,FALSE) -> 42236 | B30: =VLOOKUP(C30,Samples!A:C,3,FALSE) -> CSITE 03 | C30: =LEFT(D30,LEN(D30)-3) -> X11.48 | D30: X11.48.H1 | K30: 3.6 | L30: 15 | M30: =L30*PI()*K30^2 -> 610.72561 | O30: 2.2096666 | P30: =SUMIF(D:D,D30,L:L)/COUNTIF(D:D,D30)*100 -> 1500 | Q30: =O30*P30*1000 -> 3314499.9
A31: =VLOOKUP(D31,'Sample ID by Horizon'!A:B,2,FALSE) -> 42236 | B31: =VLOOKUP(C31,Samples!A:C,3,FALSE) -> CSITE 03 | C31: =LEFT(D31,LEN(D31)-3) -> X11.48 | D31: X11.48.H2 | J31: 845 | K31: 3.6 | L31: 15 | M31: =L31*PI()*K31^2 -> 610.72561 | N31: =J31/M31 -> 1.3836001 | O31: =SUMIF(D:D,D31,N:N)/COUNTIF(D:D,D31) -> 1.3836001 | P31: =SUMIF(D:D,D31,L:L)/COUNTIF(D:D,D31)*100 -> 1500 | Q31: =O31*P31*1000 -> 2075400.1
A32: =VLOOKUP(D32,'Sample ID by Horizon'!A:B,2,FALSE) -> 42236 | B32: =VLOOKUP(C32,Samples!A:C,3,FALSE) -> CSITE 04 | C32: =LEFT(D32,LEN(D32)-3) -> X11.49 | D32: X11.49.H1 | K32: 3.6 | L32: 15 | M32: =L32*PI()*K32^2 -> 610.72561 | O32: 2.2964486 | P32: =SUMIF(D:D,D32,L:L)/COUNTIF(D:D,D32)*100 -> 1500 | Q32: =O32*P32*1000 -> 3444673
A33: =VLOOKUP(D33,'Sample ID by Horizon'!A:B,2,FALSE) -> 42236 | B33: =VLOOKUP(C33,Samples!A:C,3,FALSE) -> CSITE 04 | C33: =LEFT(D33,LEN(D33)-3) -> X11.49 | D33: X11.49.H2 | J33: 873 | K33: 3.6 | L33: 15 | M33: =L33*PI()*K33^2 -> 610.72561 | N33: =J33/M33 -> 1.4294472 | O33: =SUMIF(D:D,D33,N:N)/COUNTIF(D:D,D33) -> 1.4294472 | P33: =SUMIF(D:D,D33,L:L)/COUNTIF(D:D,D33)*100 -> 1500 | Q33: =O33*P33*1000 -> 2144170.8
A34: =VLOOKUP(D34,'Sample ID by Horizon'!A:B,2,FALSE) -> 42241 | B34: =VLOOKUP(C34,Samples!A:C,3,FALSE) -> CSITE 05 | C34: =LEFT(D34,LEN(D34)-3) -> X11.54 | D34: X11.54.H1 | K34: 3.6 | L34: 15 | M34: =L34*PI()*K34^2 -> 610.72561 | O34: 2.2137601 | P34: =SUMIF(D:D,D34,L:L)/COUNTIF(D:D,D34)*100 -> 1500 | Q34: =O34*P34*1000 -> 3320640.2
A35: =VLOOKUP(D35,'Sample ID by Horizon'!A:B,2,FALSE) -> 42241 | B35: =VLOOKUP(C35,Samples!A:C,3,FALSE) -> CSITE 05 | C35: =LEFT(D35,LEN(D35)-3) -> X11.54 | D35: X11.54.H2 | J35: 919 | K35: 3.6 | L35: 15 | M35: =L35*PI()*K35^2 -> 610.72561 | N35: =J35/M35 -> 1.5047674 | O35: =SUMIF(D:D,D35,N:N)/COUNTIF(D:D,D35) -> 1.5047674 | P35: =SUMIF(D:D,D35,L:L)/COUNTIF(D:D,D35)*100 -> 1500 | Q35: =O35*P35*1000 -> 2257151.1
A36: =VLOOKUP(D36,'Sample ID by Horizon'!A:B,2,FALSE) -> 42242 | B36: =VLOOKUP(C36,Samples!A:C,3,FALSE) -> CSITE 06 | C36: =LEFT(D36,LEN(D36)-3) -> X11.55 | D36: X11.55.H1 | K36: 3.6 | L36: 15 | M36: =L36*PI()*K36^2 -> 610.72561 | O36: 1.9566889 | P36: =SUMIF(D:D,D36,L:L)/COUNTIF(D:D,D36)*100 -> 1500 | Q36: =O36*P36*1000 -> 2935033.3
A37: =VLOOKUP(D37,'Sample ID by Horizon'!A:B,2,FALSE) -> 42242 | B37: =VLOOKUP(C37,Samples!A:C,3,FALSE) -> CSITE 06 | C37: =LEFT(D37,LEN(D37)-3) -> X11.55 | D37: X11.55.H2 | J37: 787 | K37: 3.6 | L37: 15 | M37: =L37*PI()*K37^2 -> 610.72561 | N37: =J37/M37 -> 1.2886311 | O37: =SUMIF(D:D,D37,N:N)/COUNTIF(D:D,D37) -> 1.2886311 | P37: =SUMIF(D:D,D37,L:L)/COUNTIF(D:D,D37)*100 -> 1500 | Q37: =O37*P37*1000 -> 1932946.6
A38: =VLOOKUP(D38,'Sample ID by Horizon'!A:B,2,FALSE) -> 42244 | B38: =VLOOKUP(C38,Samples!A:C,3,FALSE) -> CSITE 07 | C38: =LEFT(D38,LEN(D38)-3) -> X11.56 | D38: X11.56.H1 | K38: 3.6 | L38: 15 | M38: =L38*PI()*K38^2 -> 610.72561 | O38: 2.2841682 | P38: =SUMIF(D:D,D38,L:L)/COUNTIF(D:D,D38)*100 -> 1500 | Q38: =O38*P38*1000 -> 3426252.2
A39: =VLOOKUP(D39,'Sample ID by Horizon'!A:B,2,FALSE) -> 42244 | B39: =VLOOKUP(C39,Samples!A:C,3,FALSE) -> CSITE 07 | C39: =LEFT(D39,LEN(D39)-3) -> X11.56 | D39: X11.56.H2 | J39: 843 | K39: 3.6 | L39: 15 | M39: =L39*PI()*K39^2 -> 610.72561 | N39: =J39/M39 -> 1.3803253 | O39: =SUMIF(D:D,D39,N:N)/COUNTIF(D:D,D39) -> 1.3803253 | P39: =SUMIF(D:D,D39,L:L)/COUNTIF(D:D,D39)*100 -> 1500 | Q39: =O39*P39*1000 -> 2070487.9
A40: =VLOOKUP(D40,'Sample ID by Horizon'!A:B,2,FALSE) -> 42247 | B40: =VLOOKUP(C40,Samples!A:C,3,FALSE) -> CSITE 08 | C40: =LEFT(D40,LEN(D40)-3) -> X11.57 | D40: X11.57.H1 | K40: 3.6 | L40: 15 | M40: =L40*PI()*K40^2 -> 610.72561 | O40: 2.2530576 | P40: =SUMIF(D:D,D40,L:L)/COUNTIF(D:D,D40)*100 -> 1500 | Q40: =O40*P40*1000 -> 3379586.4
A41: =VLOOKUP(D41,'Sample ID by Horizon'!A:B,2,FALSE) -> 42247 | B41: =VLOOKUP(C41,Samples!A:C,3,FALSE) -> CSITE 08 | C41: =LEFT(D41,LEN(D41)-3) -> X11.57 | D41: X11.57.H2 | J41: 983 | K41: 3.6 | L41: 15 | M41: =L41*PI()*K41^2 -> 610.72561 | N41: =J41/M41 -> 1.6095608 | O41: =SUMIF(D:D,D41,N:N)/COUNTIF(D:D,D41) -> 1.6095608 | P41: =SUMIF(D:D,D41,L:L)/COUNTIF(D:D,D41)*100 -> 1500 | Q41: =O41*P41*1000 -> 2414341.2
A42: =VLOOKUP(D42,'Sample ID by Horizon'!A:B,2,FALSE) -> 42249 | B42: =VLOOKUP(C42,Samples!A:C,3,FALSE) -> CSITE 09 | C42: =LEFT(D42,LEN(D42)-3) -> X11.58 | D42: X11.58.H1 | K42: 3.6 | L42: 15 | M42: =L42*PI()*K42^2 -> 610.72561 | O42: 1.7945866 | P42: =SUMIF(D:D,D42,L:L)/COUNTIF(D:D,D42)*100 -> 1500 | Q42: =O42*P42*1000 -> 2691879.9
A43: =VLOOKUP(D43,'Sample ID by Horizon'!A:B,2,FALSE) -> 42249 | B43: =VLOOKUP(C43,Samples!A:C,3,FALSE) -> CSITE 09 | C43: =LEFT(D43,LEN(D43)-3) -> X11.58 | D43: X11.58.H2 | J43: 733 | K43: 3.6 | L43: 15 | M43: =L43*PI()*K43^2 -> 610.72561 | N43: =J43/M43 -> 1.2002117 | O43: =SUMIF(D:D,D43,N:N)/COUNTIF(D:D,D43) -> 1.2002117 | P43: =SUMIF(D:D,D43,L:L)/COUNTIF(D:D,D43)*100 -> 1500 | Q43: =O43*P43*1000 -> 1800317.5
A44: =VLOOKUP(D44,'Sample ID by Horizon'!A:B,2,FALSE) -> 42249 | B44: =VLOOKUP(C44,Samples!A:C,3,FALSE) -> CSITE 10 | C44: =LEFT(D44,LEN(D44)-3) -> X11.59 | D44: X11.59.H1 | K44: 3.6 | L44: 15 | M44: =L44*PI()*K44^2 -> 610.72561 | O44: 2.3120039 | P44: =SUMIF(D:D,D44,L:L)/COUNTIF(D:D,D44)*100 -> 1500 | Q44: =O44*P44*1000 -> 3468005.9
A45: =VLOOKUP(D45,'Sample ID by Horizon'!A:B,2,FALSE) -> 42249 | B45: =VLOOKUP(C45,Samples!A:C,3,FALSE) -> CSITE 10 | C45: =LEFT(D45,LEN(D45)-3) -> X11.59 | D45: X11.59.H2 | J45: 723 | K45: 3.6 | L45: 15 | M45: =L45*PI()*K45^2 -> 610.72561 | N45: =J45/M45 -> 1.1838377 | O45: =SUMIF(D:D,D45,N:N)/COUNTIF(D:D,D45) -> 1.1838377 | P45: =SUMIF(D:D,D45,L:L)/COUNTIF(D:D,D45)*100 -> 1500 | Q45: =O45*P45*1000 -> 1775756.5
A46: =VLOOKUP(D46,'Sample ID by Horizon'!A:B,2,FALSE) -> 42249 | B46: =VLOOKUP(C46,Samples!A:C,3,FALSE) -> CSITE 11 | C46: =LEFT(D46,LEN(D46)-3) -> X11.60 | D46: X11.60.H1 | K46: 3.6 | L46: 15 | M46: =L46*PI()*K46^2 -> 610.72561 | O46: 2.0688505 | P46: =SUMIF(D:D,D46,L:L)/COUNTIF(D:D,D46)*100 -> 1500 | Q46: =O46*P46*1000 -> 3103275.8
A47: =VLOOKUP(D47,'Sample ID by Horizon'!A:B,2,FALSE) -> 42249 | B47: =VLOOKUP(C47,Samples!A:C,3,FALSE) -> CSITE 11 | C47: =LEFT(D47,LEN(D47)-3) -> X11.60 | D47: X11.60.H2 | J47: 1079 | K47: 3.6 | L47: 15 | M47: =L47*PI()*K47^2 -> 610.72561 | N47: =J47/M47 -> 1.7667509 | O47: =SUMIF(D:D,D47,N:N)/COUNTIF(D:D,D47) -> 1.7667509 | P47: =SUMIF(D:D,D47,L:L)/COUNTIF(D:D,D47)*100 -> 1500 | Q47: =O47*P47*1000 -> 2650126.3
A48: =VLOOKUP(D48,'Sample ID by Horizon'!A:B,2,FALSE) -> 42249 | B48: =VLOOKUP(C48,Samples!A:C,3,FALSE) -> CSITE 12 | C48: =LEFT(D48,LEN(D48)-3) -> X11.61 | D48: X11.61.H1 | K48: 3.6 | L48: 15 | M48: =L48*PI()*K48^2 -> 610.72561 | O48: 2.677962 | P48: =SUMIF(D:D,D48,L:L)/COUNTIF(D:D,D48)*100 -> 1500 | Q48: =O48*P48*1000 -> 4016943
A49: =VLOOKUP(D49,'Sample ID by Horizon'!A:B,2,FALSE) -> 42249 | B49: =VLOOKUP(C49,Samples!A:C,3,FALSE) -> CSITE 12 | C49: =LEFT(D49,LEN(D49)-3) -> X11.61 | D49: X11.61.H2 | J49: 987 | K49: 3.6 | L49: 15 | M49: =L49*PI()*K49^2 -> 610.72561 | N49: =J49/M49 -> 1.6161104 | O49: =SUMIF(D:D,D49,N:N)/COUNTIF(D:D,D49) -> 1.6161104 | P49: =SUMIF(D:D,D49,L:L)/COUNTIF(D:D,D49)*100 -> 1500 | Q49: =O49*P49*1000 -> 2424165.6
A50: =VLOOKUP(D50,'Sample ID by Horizon'!A:B,2,FALSE) -> 42271 | B50: =VLOOKUP(C50,Samples!A:C,3,FALSE) -> CSITE 01 | C50: =LEFT(D50,LEN(D50)-3) -> X11.64 | D50: X11.64.H1 | J50: 1419 | K50: 3.6 | L50: 15 | M50: =L50*PI()*K50^2 -> 610.72561 | N50: =J50/M50 -> 2.3234657 | O50: =SUMIF(D:D,D50,N:N)/COUNTIF(D:D,D50) -> 2.3234657 | P50: =SUMIF(D:D,D50,L:L)/COUNTIF(D:D,D50)*100 -> 1500 | Q50: =O50*P50*1000 -> 3485198.5
A51: =VLOOKUP(D51,'Sample ID by Horizon'!A:B,2,FALSE) -> 42272 | B51: =VLOOKUP(C51,Samples!A:C,3,FALSE) -> CSITE 02 | C51: =LEFT(D51,LEN(D51)-3) -> X11.65 | D51: X11.65.H1 | J51: 1572 | K51: 3.6 | L51: 15 | M51: =L51*PI()*K51^2 -> 610.72561 | N51: =J51/M51 -> 2.5739874 | O51: =SUMIF(D:D,D51,N:N)/COUNTIF(D:D,D51) -> 2.5739874 | P51: =SUMIF(D:D,D51,L:L)/COUNTIF(D:D,D51)*100 -> 1500 | Q51: =O51*P51*1000 -> 3860981
A52: =VLOOKUP(D52,'Sample ID by Horizon'!A:B,2,FALSE) -> 42275 | B52: =VLOOKUP(C52,Samples!A:C,3,FALSE) -> CSITE 03 | C52: =LEFT(D52,LEN(D52)-3) -> X11.66 | D52: X11.66.H1 | J52: 1342 | K52: 3.6 | L52: 15 | M52: =L52*PI()*K52^2 -> 610.72561 | N52: =J52/M52 -> 2.1973861 | O52: =SUMIF(D:D,D52,N:N)/COUNTIF(D:D,D52) -> 2.1973861 | P52: =SUMIF(D:D,D52,L:L)/COUNTIF(D:D,D52)*100 -> 1500 | Q52: =O52*P52*1000 -> 3296079.2
...

Sheet Elutriation
A1: Date | B1: Sample ID (Shared Identifier) | C1: Round | D1: Wt Silt | E1: Wt Clay | F1: Total Wt | G1: Silt (%) | H1: Clay (%) | I1: Mean Silt (%) | J1: Mean Clay (%)
A2: =VLOOKUP(B2,'Sample ID by Horizon'!A:B,2,FALSE) -> 42649 | B2: x11.255.c1 | C2: 1 | D2: 7 | E2: 3 | F2: =SUM(D2:E2) -> 10 | G2: =D2/F2*100 -> 70 | H2: =E2/F2*100 -> 30 | I2: =AVERAGE(G2:G4) -> 71 | J2: =AVERAGE(H2:H4) -> 29
A3: =VLOOKUP(B3,'Sample ID by Horizon'!A:B,2,FALSE) -> 42649 | B3: x11.255.c1 | C3: 2 | D3: 7.1 | E3: 2.9 | F3: =SUM(D3:E3) -> 10 | G3: =D3/F3*100 -> 71 | H3: =E3/F3*100 -> 29 | I3: =I2 -> 71 | J3: =J2 -> 29
A4: =VLOOKUP(B4,'Sample ID by Horizon'!A:B,2,FALSE) -> 42649 | B4: x11.255.c1 | C4: 3 | D4: 7.2 | E4: 2.8 | F4: =SUM(D4:E4) -> 10 | G4: =D4/F4*100 -> 72 | H4: =E4/F4*100 -> 28 | I4: =I2 -> 71 | J4: =J2 -> 29
A5: =VLOOKUP(B5,'Sample ID by Horizon'!A:B,2,FALSE) -> 42649 | B5: X11.255.C2 | C5: =C2 -> 1 | D5: 7.3 | E5: 2.7 | F5: =SUM(D5:E5) -> 10 | G5: =D5/F5*100 -> 73 | H5: =E5/F5*100 -> 27 | I5: =AVERAGE(G5:G7) -> 74 | J5: =AVERAGE(H5:H7) -> 26
A6: =VLOOKUP(B6,'Sample ID by Horizon'!A:B,2,FALSE) -> 42649 | B6: X11.255.C2 | C6: =C3 -> 2 | D6: 7.4 | E6: 2.6 | F6: =SUM(D6:E6) -> 10 | G6: =D6/F6*100 -> 74 | H6: =E6/F6*100 -> 26 | I6: =I5 -> 74 | J6: =J5 -> 26
A7: =VLOOKUP(B7,'Sample ID by Horizon'!A:B,2,FALSE) -> 42649 | B7: X11.255.C2 | C7: =C4 -> 3 | D7: 7.5 | E7: 2.5 | F7: =SUM(D7:E7) -> 10 | G7: =D7/F7*100 -> 75 | H7: =E7/F7*100 -> 25 | I7: =I5 -> 74 | J7: =J5 -> 26
A8: =VLOOKUP(B8,'Sample ID by Horizon'!A:B,2,FALSE) -> 42649 | B8: X11.255.C3 | C8: =C5 -> 1 | D8: 7.6 | E8: 2.4 | F8: =SUM(D8:E8) -> 10 | G8: =D8/F8*100 -> 76 | H8: =E8/F8*100 -> 24 | I8: =AVERAGE(G8:G10) -> 77 | J8: =AVERAGE(H8:H10) -> 23
A9: =VLOOKUP(B9,'Sample ID by Horizon'!A:B,2,FALSE) -> 42649 | B9: X11.255.C3 | C9: =C6 -> 2 | D9: 7.7 | E9: 2.3 | F9: =SUM(D9:E9) -> 10 | G9: =D9/F9*100 -> 77 | H9: =E9/F9*100 -> 23 | I9: =I8 -> 77 | J9: =J8 -> 23
A10: =VLOOKUP(B10,'Sample ID by Horizon'!A:B,2,FALSE) -> 42649 | B10: X11.255.C3 | C10: =C7 -> 3 | D10: 7.8 | E10: 2.2 | F10: =SUM(D10:E10) -> 10 | G10: =D10/F10*100 -> 78 | H10: =E10/F10*100 -> 22 | I10: =I8 -> 77 | J10: =J8 -> 23
A11: =VLOOKUP(B11,'Sample ID by Horizon'!A:B,2,FALSE) -> 42649 | B11: X11.255.C4 | C11: =C8 -> 1 | D11: 7.9 | E11: 2.1 | F11: =SUM(D11:E11) -> 10 | G11: =D11/F11*100 -> 79 | H11: =E11/F11*100 -> 21 | I11: =AVERAGE(G11:G13) -> 80 | J11: =AVERAGE(H11:H13) -> 20
A12: =VLOOKUP(B12,'Sample ID by Horizon'!A:B,2,FALSE) -> 42649 | B12: X11.255.C4 | C12: =C9 -> 2 | D12: 8 | E12: 2 | F12: =SUM(D12:E12) -> 10 | G12: =D12/F12*100 -> 80 | H12: =E12/F12*100 -> 20 | I12: =I11 -> 80 | J12: =J11 -> 20
A13: =VLOOKUP(B13,'Sample ID by Horizon'!A:B,2,FALSE) -> 42649 | B13: X11.255.C4 | C13: =C10 -> 3 | D13: 8.1 | E13: 1.9 | F13: =SUM(D13:E13) -> 10 | G13: =D13/F13*100 -> 81 | H13: =E13/F13*100 -> 19 | I13: =I11 -> 80 | J13: =J11 -> 20
A14: =VLOOKUP(B14,'Sample ID by Horizon'!A:B,2,FALSE) -> 42649 | B14: X11.255.C5 | C14: =C11 -> 1 | D14: 8.2 | E14: 1.8 | F14: =SUM(D14:E14) -> 10 | G14: =D14/F14*100 -> 82 | H14: =E14/F14*100 -> 18 | I14: =AVERAGE(G14:G16) -> 83 | J14: =AVERAGE(H14:H16) -> 17
A15: =VLOOKUP(B15,'Sample ID by Horizon'!A:B,2,FALSE) -> 42649 | B15: X11.255.C5 | C15: =C12 -> 2 | D15: 8.3 | E15: 1.7 | F15: =SUM(D15:E15) -> 10 | G15: =D15/F15*100 -> 83 | H15: =E15/F15*100 -> 17 | I15: =I14 -> 83 | J15: =J14 -> 17
A16: =VLOOKUP(B16,'Sample ID by Horizon'!A:B,2,FALSE) -> 42649 | B16: X11.255.C5 | C16: =C13 -> 3 | D16: 8.4 | E16: 1.6 | F16: =SUM(D16:E16) -> 10 | G16: =D16/F16*100 -> 84 | H16: =E16/F16*100 -> 16 | I16: =I14 -> 83 | J16: =J14 -> 17
A17: =VLOOKUP(B17,'Sample ID by Horizon'!A:B,2,FALSE) -> 42500 | B17: X11.207.C1 | C17: =C14 -> 1 | D17: 8.5 | E17: 1.5 | F17: =SUM(D17:E17) -> 10 | G17: =D17/F17*100 -> 85 | H17: =E17/F17*100 -> 15 | I17: =AVERAGE(G17:G19) -> 86 | J17: =AVERAGE(H17:H19) -> 14
A18: =VLOOKUP(B18,'Sample ID by Horizon'!A:B,2,FALSE) -> 42500 | B18: X11.207.C1 | C18: =C15 -> 2 | D18: 8.6 | E18: 1.4 | F18: =SUM(D18:E18) -> 10 | G18: =D18/F18*100 -> 86 | H18: =E18/F18*100 -> 14 | I18: =I17 -> 86 | J18: =J17 -> 14
A19: =VLOOKUP(B19,'Sample ID by Horizon'!A:B,2,FALSE) -> 42500 | B19: X11.207.C1 | C19: =C16 -> 3 | D19: 8.7 | E19: 1.3 | F19: =SUM(D19:E19) -> 10 | G19: =D19/F19*100 -> 87 | H19: =E19/F19*100 -> 13 | I19: =I17 -> 86 | J19: =J17 -> 14
A20: =VLOOKUP(B20,'Sample ID by Horizon'!A:B,2,FALSE) -> 42500 | B20: X11.207.C2 | C20: =C17 -> 1 | D20: 8.8 | E20: 1.2 | F20: =SUM(D20:E20) -> 10 | G20: =D20/F20*100 -> 88 | H20: =E20/F20*100 -> 12 | I20: =AVERAGE(G20:G22) -> 89 | J20: =AVERAGE(H20:H22) -> 11
A21: =VLOOKUP(B21,'Sample ID by Horizon'!A:B,2,FALSE) -> 42500 | B21: X11.207.C2 | C21: =C18 -> 2 | D21: 8.9 | E21: 1.1 | F21: =SUM(D21:E21) -> 10 | G21: =D21/F21*100 -> 89 | H21: =E21/F21*100 -> 11 | I21: =I20 -> 89 | J21: =J20 -> 11
A22: =VLOOKUP(B22,'Sample ID by Horizon'!A:B,2,FALSE) -> 42500 | B22: X11.207.C2 | C22: =C19 -> 3 | D22: 9 | E22: 1 | F22: =SUM(D22:E22) -> 10 | G22: =D22/F22*100 -> 90 | H22: =E22/F22*100 -> 10 | I22: =I20 -> 89 | J22: =J20 -> 11
A23: =VLOOKUP(B23,'Sample ID by Horizon'!A:B,2,FALSE) -> 42500 | B23: X11.207.C3 | C23: =C20 -> 1 | D23: 8.9 | E23: 1.1 | F23: =SUM(D23:E23) -> 10 | G23: =D23/F23*100 -> 89 | H23: =E23/F23*100 -> 11 | I23: =AVERAGE(G23:G25) -> 88 | J23: =AVERAGE(H23:H25) -> 12
A24: =VLOOKUP(B24,'Sample ID by Horizon'!A:B,2,FALSE) -> 42500 | B24: X11.207.C3 | C24: =C21 -> 2 | D24: 8.8 | E24: 1.2 | F24: =SUM(D24:E24) -> 10 | G24: =D24/F24*100 -> 88 | H24: =E24/F24*100 -> 12 | I24: =I23 -> 88 | J24: =J23 -> 12
A25: =VLOOKUP(B25,'Sample ID by Horizon'!A:B,2,FALSE) -> 42500 | B25: X11.207.C3 | C25: =C22 -> 3 | D25: 8.7 | E25: 1.3 | F25: =SUM(D25:E25) -> 10 | G25: =D25/F25*100 -> 87 | H25: =E25/F25*100 -> 13 | I25: =I23 -> 88 | J25: =J23 -> 12
A26: =VLOOKUP(B26,'Sample ID by Horizon'!A:B,2,FALSE) -> 42500 | B26: X11.207.C4 | C26: =C23 -> 1 | D26: 8.6 | E26: 1.4 | F26: =SUM(D26:E26) -> 10 | G26: =D26/F26*100 -> 86 | H26: =E26/F26*100 -> 14 | I26: =AVERAGE(G26:G28) -> 85 | J26: =AVERAGE(H26:H28) -> 15
A27: =VLOOKUP(B27,'Sample ID by Horizon'!A:B,2,FALSE) -> 42500 | B27: X11.207.C4 | C27: =C24 -> 2 | D27: 8.5 | E27: 1.5 | F27: =SUM(D27:E27) -> 10 | G27: =D27/F27*100 -> 85 | H27: =E27/F27*100 -> 15 | I27: =I26 -> 85 | J27: =J26 -> 15
A28: =VLOOKUP(B28,'Sample ID by Horizon'!A:B,2,FALSE) -> 42500 | B28: X11.207.C4 | C28: =C25 -> 3 | D28: 8.4 | E28: 1.6 | F28: =SUM(D28:E28) -> 10 | G28: =D28/F28*100 -> 84 | H28: =E28/F28*100 -> 16 | I28: =I26 -> 85 | J28: =J26 -> 15
A29: =VLOOKUP(B29,'Sample ID by Horizon'!A:B,2,FALSE) -> 42888 | B29: X15.52.C1 | C29: =C26 -> 1 | D29: 8.3 | E29: 1.7 | F29: =SUM(D29:E29) -> 10 | G29: =D29/F29*100 -> 83 | H29: =E29/F29*100 -> 17 | I29: =AVERAGE(G29:G31) -> 82 | J29: =AVERAGE(H29:H31) -> 18
A30: =VLOOKUP(B30,'Sample ID by Horizon'!A:B,2,FALSE) -> 42888 | B30: X15.52.C1 | C30: =C27 -> 2 | D30: 8.2 | E30: 1.8 | F30: =SUM(D30:E30) -> 10 | G30: =D30/F30*100 -> 82 | H30: =E30/F30*100 -> 18 | I30: =I29 -> 82 | J30: =J29 -> 18
A31: =VLOOKUP(B31,'Sample ID by Horizon'!A:B,2,FALSE) -> 42888 | B31: X15.52.C1 | C31: =C28 -> 3 | D31: 8.1 | E31: 1.9 | F31: =SUM(D31:E31) -> 10 | G31: =D31/F31*100 -> 81 | H31: =E31/F31*100 -> 19 | I31: =I29 -> 82 | J31: =J29 -> 18
A32: =VLOOKUP(B32,'Sample ID by Horizon'!A:B,2,FALSE) -> 42888 | B32: X15.52.C2 | C32: =C29 -> 1 | D32: 8 | E32: 2 | F32: =SUM(D32:E32) -> 10 | G32: =D32/F32*100 -> 80 | H32: =E32/F32*100 -> 20 | I32: =AVERAGE(G32:G34) -> 79 | J32: =AVERAGE(H32:H34) -> 21
A33: =VLOOKUP(B33,'Sample ID by Horizon'!A:B,2,FALSE) -> 42888 | B33: X15.52.C2 | C33: =C30 -> 2 | D33: 7.9 | E33: 2.1 | F33: =SUM(D33:E33) -> 10 | G33: =D33/F33*100 -> 79 | H33: =E33/F33*100 -> 21 | I33: =I32 -> 79 | J33: =J32 -> 21
A34: =VLOOKUP(B34,'Sample ID by Horizon'!A:B,2,FALSE) -> 42888 | B34: X15.52.C2 | C34: =C31 -> 3 | D34: 7.8 | E34: 2.2 | F34: =SUM(D34:E34) -> 10 | G34: =D34/F34*100 -> 78 | H34: =E34/F34*100 -> 22 | I34: =I32 -> 79 | J34: =J32 -> 21
A35: =VLOOKUP(B35,'Sample ID by Horizon'!A:B,2,FALSE) -> 42888 | B35: X15.52.C3 | C35: =C32 -> 1 | D35: 7.7 | E35: 2.3 | F35: =SUM(D35:E35) -> 10 | G35: =D35/F35*100 -> 77 | H35: =E35/F35*100 -> 23 | I35: =AVERAGE(G35:G37) -> 76 | J35: =AVERAGE(H35:H37) -> 24
A36: =VLOOKUP(B36,'Sample ID by Horizon'!A:B,2,FALSE) -> 42888 | B36: X15.52.C3 | C36: =C33 -> 2 | D36: 7.6 | E36: 2.4 | F36: =SUM(D36:E36) -> 10 | G36: =D36/F36*100 -> 76 | H36: =E36/F36*100 -> 24 | I36: =I35 -> 76 | J36: =J35 -> 24
A37: =VLOOKUP(B37,'Sample ID by Horizon'!A:B,2,FALSE) -> 42888 | B37: X15.52.C3 | C37: =C34 -> 3 | D37: 7.5 | E37: 2.5 | F37: =SUM(D37:E37) -> 10 | G37: =D37/F37*100 -> 75 | H37: =E37/F37*100 -> 25 | I37: =I35 -> 76 | J37: =J35 -> 24
A38: =VLOOKUP(B38,'Sample ID by Horizon'!A:B,2,FALSE) -> 42888 | B38: X15.52.C4 | C38: =C35 -> 1 | D38: 7.4 | E38: 2.6 | F38: =SUM(D38:E38) -> 10 | G38: =D38/F38*100 -> 74 | H38: =E38/F38*100 -> 26 | I38: =AVERAGE(G38:G40) -> 73 | J38: =AVERAGE(H38:H40) -> 27
A39: =VLOOKUP(B39,'Sample ID by Horizon'!A:B,2,FALSE) -> 42888 | B39: X15.52.C4 | C39: =C36 -> 2 | D39: 7.3 | E39: 2.7 | F39: =SUM(D39:E39) -> 10 | G39: =D39/F39*100 -> 73 | H39: =E39/F39*100 -> 27 | I39: =I38 -> 73 | J39: =J38 -> 27
A40: =VLOOKUP(B40,'Sample ID by Horizon'!A:B,2,FALSE) -> 42888 | B40: X15.52.C4 | C40: =C37 -> 3 | D40: 7.2 | E40: 2.8 | F40: =SUM(D40:E40) -> 10 | G40: =D40/F40*100 -> 72 | H40: =E40/F40*100 -> 28 | I40: =I38 -> 73 | J40: =J38 -> 27
...

Sheet Dry Sieve
C1: WA
A2: Date | B2: Sample ID (Shared Identifier) | C2: Weight #5 [4mm] | D2: Weight #10 [2mm] | E2: Weight #18 [1mm] | F2: Weight #35 [0.5mm] | G2: Weight #60 [0.25mm] | H2: Weight #120 [0.125mm] | I2: Weight #200 [.075mm] | J2: Weight <200 [<.075mm] | K2: Sum WT (g)
A3: =VLOOKUP(B3,'Sample ID by Horizon'!A:B,2,FALSE) -> 42500 | B3: X11.207.C1 | C3: 21.25 | D3: 10.86 | E3: 6.75 | F3: 5.09 | G3: 4.88 | H3: 4.62 | I3: 2.9 | J3: 2.58 | K3: =SUM(C3:J3) -> 58.93
A4: =VLOOKUP(B4,'Sample ID by Horizon'!A:B,2,FALSE) -> 42500 | B4: X11.207.C2 | C4: 31.55 | D4: 9.96 | E4: 6.87 | F4: 4.72 | G4: 3.88 | H4: 2.71 | I4: 1.41 | J4: 0.75 | K4: =SUM(C4:J4) -> 61.85
A5: =VLOOKUP(B5,'Sample ID by Horizon'!A:B,2,FALSE) -> 42500 | B5: X11.207.C3 | C5: 37.62 | D5: 21.5 | E5: 15.99 | F5: 14.51 | G5: 17.07 | H5: 12.52 | I5: 6.93 | J5: 4.75 | K5: =SUM(C5:J5) -> 130.89
A6: =VLOOKUP(B6,'Sample ID by Horizon'!A:B,2,FALSE) -> 42499 | B6: X11.208.C1 | C6: 60.84 | D6: 23.25 | E6: 17.05 | F6: 11.43 | G6: 6.6 | H6: 2.76 | I6: 0.94 | J6: 0.61 | K6: =SUM(C6:J6) -> 123.48
A7: =VLOOKUP(B7,'Sample ID by Horizon'!A:B,2,FALSE) -> 42499 | B7: X11.208.C2 | C7: 74.12 | D7: 25.14 | E7: 13.5 | F7: 5.23 | G7: 1.09 | H7: 0.3 | I7: 0.15 | J7: 0.14 | K7: =SUM(C7:J7) -> 119.67
A8: =VLOOKUP(B8,'Sample ID by Horizon'!A:B,2,FALSE) -> 42499 | B8: X11.208.C3 | C8: 155.61 | D8: 23.86 | E8: 13.44 | F8: 5.42 | G8: 1.61 | H8: 0.59 | I8: 0.28 | J8: 0.29 | K8: =SUM(C8:J8) -> 201.1
A9: =VLOOKUP(B9,'Sample ID by Horizon'!A:B,2,FALSE) -> 42505 | B9: X11.209.C1 | C9: 71.14 | D9: 32.5 | E9: 25.97 | F9: 13.67 | G9: 4.28 | H9: 1.03 | I9: 0.38 | J9: 0.5 | K9: =SUM(C9:J9) -> 149.47
A10: =VLOOKUP(B10,'Sample ID by Horizon'!A:B,2,FALSE) -> 42505 | B10: X11.209.C2 | C10: 101.47 | D10: 22.99 | E10: 13.42 | F10: 5.24 | G10: 1.57 | H10: 0.5 | I10: 0.24 | J10: 0.35 | K10: =SUM(C10:J10) -> 145.78
A11: =VLOOKUP(B11,'Sample ID by Horizon'!A:B,2,FALSE) -> 42505 | B11: X11.209.C3 | C11: 114.95 | D11: 16.26 | E11: 3.82 | F11: 0.86 | G11: 0.29 | H11: 0.12 | I11: 0.21 | J11: 0.1 | K11: =SUM(C11:J11) -> 136.61
A12: =VLOOKUP(B12,'Sample ID by Horizon'!A:B,2,FALSE) -> 42506 | B12: X11.210.C1 | C12: 44.23 | D12: 14.05 | E12: 16.06 | F12: 17.16 | G12: 12.97 | H12: 5.16 | I12: 1.81 | J12: 1.25 | K12: =SUM(C12:J12) -> 112.69
A13: =VLOOKUP(B13,'Sample ID by Horizon'!A:B,2,FALSE) -> 42506 | B13: X11.210.C2 | C13: 42.05 | D13: 19.28 | E13: 20.75 | F13: 19.91 | G13: 14.52 | H13: 5.13 | I13: 1.54 | J13: 0.94 | K13: =SUM(C13:J13) -> 124.12
A14: =VLOOKUP(B14,'Sample ID by Horizon'!A:B,2,FALSE) -> 42506 | B14: X11.210.C3 | C14: 49.96 | D14: 27.13 | E14: 29.58 | F14: 22.96 | G14: 13.3 | H14: 4.77 | I14: 1.67 | J14: 1.18 | K14: =SUM(C14:J14) -> 150.55
... A69: =VLOOKUP(B69,'Sample ID by Horizon'!A:B,2,FALSE) -> 42655 | B69: X11.262.C5 | C69: 1029 | D69: 301.02 | E69: 209.78 | F69: 132.62 | G69: 107.74 | H69: 161.82 | I69: 158.92 | J69: 236.6 | K69: =SUM(C69:J69) -> 2337.5
A70: =VLOOKUP(B70,'Sample ID by Horizon'!A:B,2,FALSE) -> 42655 | B70: X11.266.C1 | K70: =SUM(C70:J70) -> 0
A71: =VLOOKUP(B71,'Sample ID by Horizon'!A:B,2,FALSE) -> 42655 | B71: X11.266.C2 | K71: =SUM(C71:J71) -> 0
A72: =VLOOKUP(B72,'Sample ID by Horizon'!A:B,2,FALSE) -> 42655 | B72: X11.266.C3 | K72: =SUM(C72:J72) -> 0
A73: =VLOOKUP(B73,'Sample ID by Horizon'!A:B,2,FALSE) -> 42655 | B73: X11.266.C4 | K73: =SUM(C73:J73) -> 0
A74: =VLOOKUP(B74,'Sample ID by Horizon'!A:B,2,FALSE) -> 42655 | B74: X11.266.C5 | K74: =SUM(C74:J74) -> 0
A75: =VLOOKUP(B75,'Sample ID by Horizon'!A:B,2,FALSE) -> 42878 | B75: X15.45.C1 | C75: 37.79 | D75: 21.42 | E75: 15.61 | F75: 12.18 | G75: 10.96 | H75: 8.05 | I75: 3.91 | J75: 2.85 | K75: =SUM(C75:J75) -> 112.77
A76: =VLOOKUP(B76,'Sample ID by Horizon'!A:B,2,FALSE) -> 42878 | B76: X15.45.C2 | C76: 30.23 | D76: 29.41 | E76: 23.04 | F76: 17.64 | G76: 15.82 | H76: 13.97 | I76: 5.62 | J76: 4.02 | K76: =SUM(C76:J76) -> 139.75
A77: =VLOOKUP(B77,'Sample ID by Horizon'!A:B,2,FALSE) -> 42878 | B77: X15.45.C3 | C77: 70.08 | D77: 37.23 | E77: 22.84 | F77: 14.32 | G77: 11.79 | H77: 9.05 | I77: 4.48 | J77: 2.58 | K77: =SUM(C77:J77) -> 172.37
A78: =VLOOKUP(B78,'Sample ID by Horizon'!A:B,2,FALSE) -> 42878 | B78: X15.45.C4 | C78: 482 | D78: 193 | E78: 177 | F78: 155 | G78: 190 | H78: 135 | I78: 50 | J78: 29 | K78: =SUM(C78:J78) -> 1411
A79: =VLOOKUP(B79,'Sample ID by Horizon'!A:B,2,FALSE) -> 42878 | B79: X15.45.C5 | C79: 443 | D79: 176 | E79: 124 | F79: 85 | G79: 95 | H79: 998 | I79: 127 | J79: 80 | K79: =SUM(C79:J79) -> 2128
A80: =VLOOKUP(B80,'Sample ID by Horizon'!A:B,2,FALSE) -> 42878 | B80: X15.46.C1 | C80: 66.91 | D80: 28.51 | E80: 27.78 | F80: 17.01 | G80: 8.65 | H80: 3.02 | I80: 0.86 | J80: 0.56 | K80: =SUM(C80:J80) -> 153.3
A81: =VLOOKUP(B81,'Sample ID by Horizon'!A:B,2,FALSE) -> 42878 | B81: X15.46.C2 | C81: 81.46 | D81: 44.22 | E81: 33.27 | F81: 19.38 | G81: 9.34 | H81: 3.51 | I81: 1.05 | J81: 0.93 | K81: =SUM(C81:J81) -> 193.16
A82: =VLOOKUP(B82,'Sample ID by Horizon'!A:B,2,FALSE) -> 42878 | B82: X15.46.C3 | C82: 163.96 | D82: 34.28 | E82: 23.58 | F82: 12.57 | G82: 5.28 | H82: 2.3 | I82: 1.01 | J82: 0.7 | K82: =SUM(C82:J82) -> 243.68
A83: =VLOOKUP(B83,'Sample ID by Horizon'!A:B,2,FALSE) -> 42878 | B83: X15.46.C4 | C83: 1486 | D83: 138.91 | E83: 74.97 | F83: 37.8 | G83: 17.01 | H83: 9.51 | I83: 4.72 | J83: 10.17 | K83: =SUM(C83:J83) -> 1779.09
A84: =VLOOKUP(B84,'Sample ID by Horizon'!A:B,2,FALSE) -> 42878 | B84: X15.46.C5 | C84: 1806 | D84: 267 | E84: 160.61 | F84: 84.29 | G84: 41.62 | H84: 22.37 | I84: 18.24 | J84: 61.84 | K84: =SUM(C84:J84) -> 2461.97
A85: =VLOOKUP(B85,'Sample ID by Horizon'!A:B,2,FALSE) -> 42879 | B85: X15.47.C1 | C85: 64.48 | D85: 22.48 | E85: 19.63 | F85: 13.8 | G85: 6.71 | H85: 2.34 | I85: 0.86 | J85: 0.76 | K85: =SUM(C85:J85) -> 131.06
A86: =VLOOKUP(B86,'Sample ID by Horizon'!A:B,2,FALSE) -> 42879 | B86: X15.47.C2 | C86: 114.86 | D86: 30.51 | E86: 20.49 | F86: 9.94 | G86: 4.13 | H86: 1.59 | I86: 0.7 | J86: 0.77 | K86: =SUM(C86:J86) -> 182.99
... A174: =VLOOKUP(B174,'Sample ID by Horizon'!A:B,2,FALSE) -> 43230 | B174: 18130.CS08.C5 | C174: 113.26 | D174: 113.26 | E174: 70.13 | F174: 122.62 | G174: 157.23 | H174: 164.43 | I174: 133.18 | J174: 157.17 | K174: =SUM(C174:J174) -> 1031.28

Sheet Soil Stability-(T1)
A1: Date | B1: Sample ID (Shared Identifier) | C1: Size Classes | D1: Test | E1: Initial Wt. Soil (g) Wₒ | F1: Tin tare (g) | G1: Dry wt. w/ tin (g) | H1: Wₐ (g) | I1: Coarse wt. w/ tin (g) | J1: Wc (g) | K1: WSAi (%) | L1: Mean Wo (g) | M1: Mean Wc (g) | N1: Mean WSAi % | O1: Pawi Calculation 1 | P1: Pawi Calculation 2 | Q1: Pawi Calculation 3 | R1: Pawi Calculation 4 | S1: Pawi Calculation 5 | T1: Pawi Pantheon | U1: Stability Index (SI) by size class | V1: Whole Soil Stability Index (WSSI)
C2: WSA#5, #10, #18, #35, #60, #120, #200) | D2: (A,B,A1,B1) | K2: =IFERROR((H2-J2)/E2,"")
A3: =VLOOKUP(B2,'Sample ID by Horizon'!A:B,2,FALSE) -> #N/A | B3: X11.208.C1 | C3: #5 | D3: A | E3: 4.4 | F3: 1.72 | G3: 3.65 | H3: 1.93 | I3: 2 | J3: 0.28 | K3: 37.5 | L3: 4.2225 | M3: =AVERAGE(J3:J6) -> 0.2375 | N3: 33.903139 | O3: =VLOOKUP(B3,'Dry Sieve'!$B$2:$K$992,IF(C3="#5",2,IF(C3="#10",3,IF(C3="#18",4,IF(C3="#35",5,IF(C3="#60",6,IF(C3="#120",7,IF(C3="#200",8,IF(C3="<200",9)))))))),FALSE) -> 60.84 | P3: =SUMIFS(J:J,B:B,B3,C:C,C3)/COUNTIFS(B:B,B3,C:C,C3) -> 0.2375 | Q3: =SUMIFS(E:E,B:B,B3,C:C,C3)/COUNTIFS(B:B,B3,C:C,C3) -> 4.2225 | R3: =VLOOKUP(B3,'Dry Sieve'!$B$2:$K$992,IF(C3="#5",2,IF(C3="#10",3,IF(C3="#18",4,IF(C3="#35",5,IF(C3="#60",6,IF(C3="#120",7,IF(C3="#200",8,IF(C3="<200",9)))))))),FALSE) -> 60.84 | S3: =VLOOKUP(B3,'Dry Sieve'!$B$2:$K$992,10,FALSE) -> 123.48 | T3: 0.46499818 | U3: 0.15764898 | V3: =SUM(U3,U7,U11,U15,U19,U23,U27) -> 0.2688883
A4: =VLOOKUP(B3,'Sample ID by Horizon'!A:B,2,FALSE) -> 42499 | B4: X11.208.C1 | C4: #5 | D4: B | E4: 4.08 | F4: 1.74 | G4: 2.79 | H4: 1.05 | I4: 1.93 | J4: 0.19 | K4: 21.078431 | L4: =L3 -> 4.2225 | M4: =M3 -> 0.2375 | N4: =N3 -> 33.903139 | O4: =VLOOKUP(B4,'Dry Sieve'!$B$2:$K$992,IF(C4="#5",2,IF(C4="#10",3,IF(C4="#18",4,IF(C4="#35",5,IF(C4="#60",6,IF(C4="#120",7,IF(C4="#200",8,IF(C4="<200",9)))))))),FALSE) -> 60.84 | P4: =SUMIFS(J:J,B:B,B4,C:C,C4)/COUNTIFS(B:B,B4,C:C,C4) -> 0.2375 | Q4: =SUMIFS(E:E,B:B,B4,C:C,C4)/COUNTIFS(B:B,B4,C:C,C4) -> 4.2225 | R4: =VLOOKUP(B4,'Dry Sieve'!$B$2:$K$992,IF(C4="#5",2,IF(C4="#10",3,IF(C4="#18",4,IF(C4="#35",5,IF(C4="#60",6,IF(C4="#120",7,IF(C4="#200",8,IF(C4="<200",9)))))))),FALSE) -> 60.84 | S4: =VLOOKUP(B4,'Dry Sieve'!$B$2:$K$992,10,FALSE) -> 123.48 | T4: 0.46499818 | U4: 0.15764898 | V4: =V3 -> 0.2688883
A5: =VLOOKUP(B4,'Sample ID by Horizon'!A:B,2,FALSE) -> 42499 | B5: X11.208.C1 | C5: #5 | D5: A1 | E5: 4.1 | F5: 1.73 | G5: 3.31 | H5: 1.58 | I5: 1.94 | J5: 0.21 | K5: 33.414634 | L5: =L3 -> 4.2225 | M5: =M3 -> 0.2375 | N5: =N3 -> 33.903139 | O5: =VLOOKUP(B5,'Dry Sieve'!$B$2:$K$992,IF(C5="#5",2,IF(C5="#10",3,IF(C5="#18",4,IF(C5="#35",5,IF(C5="#60",6,IF(C5="#120",7,IF(C5="#200",8,IF(C5="<200",9)))))))),FALSE) -> 60.84 | P5: =SUMIFS(J:J,B:B,B5,C:C,C5)/COUNTIFS(B:B,B5,C:C,C5) -> 0.2375 | Q5: =SUMIFS(E:E,B:B,B5,C:C,C5)/COUNTIFS(B:B,B5,C:C,C5) -> 4.2225 | R5: =VLOOKUP(B5,'Dry Sieve'!$B$2:$K$992,IF(C5="#5",2,IF(C5="#10",3,IF(C5="#18",4,IF(C5="#35",5,IF(C5="#60",6,IF(C5="#120",7,IF(C5="#200",8,IF(C5="<200",9)))))))),FALSE) -> 60.84 | S5: =VLOOKUP(B5,'Dry Sieve'!$B$2:$K$992,10,FALSE) -> 123.48 | T5: 0.46499818 | U5: 0.15764898 | V5: =V3 -> 0.2688883
A6: =VLOOKUP(B5,'Sample ID by Horizon'!A:B,2,FALSE) -> 42499 | B6: X11.208.C1 | C6: #5 | D6: B1 | E6: 4.31 | F6: 1.74 | G6: 3.89 | H6: 2.15 | I6: 2.01 | J6: 0.27 | K6: 43.61949 | L6: =L3 -> 4.2225 | M6: =M3 -> 0.2375 | N6: =N3 -> 33.903139 | O6: =VLOOKUP(B6,'Dry Sieve'!$B$2:$K$992,IF(C6="#5",2,IF(C6="#10",3,IF(C6="#18",4,IF(C6="#35",5,IF(C6="#60",6,IF(C6="#120",7,IF(C6="#200",8,IF(C6="<200",9)))))))),FALSE) -> 60.84 | P6: =SUMIFS(J:J,B:B,B6,C:C,C6)/COUNTIFS(B:B,B6,C:C,C6) -> 0.2375 | Q6: =SUMIFS(E:E,B:B,B6,C:C,C6)/COUNTIFS(B:B,B6,C:C,C6) -> 4.2225 | R6: =VLOOKUP(B6,'Dry Sieve'!$B$2:$K$992,IF(C6="#5",2,IF(C6="#10",3,IF(C6="#18",4,IF(C6="#35",5,IF(C6="#60",6,IF(C6="#120",7,IF(C6="#200",8,IF(C6="<200",9)))))))),FALSE) -> 60.84 | S6: =VLOOKUP(B6,'Dry Sieve'!$B$2:$K$992,10,FALSE) -> 123.48 | T6: 0.46499818 | U6: 0.15764898 | V6: =V5 -> 0.2688883
A7: =VLOOKUP(B6,'Sample ID by Horizon'!A:B,2,FALSE) -> 42499 | B7: X11.208.C1 | C7: #10 | D7: A | E7: 3.93 | F7: 1.74 | G7: 3.41 | H7: 1.67 | I7: 2.36 | J7: 0.62 | K7: 26.717557 | L7: 3.9625 | M7: =AVERAGE(J7:J10) -> 0.5575 | N7: 34.100811 | O7: =VLOOKUP(B7,'Dry Sieve'!$B$2:$K$992,IF(C7="#5",2,IF(C7="#10",3,IF(C7="#18",4,IF(C7="#35",5,IF(C7="#60",6,IF(C7="#120",7,IF(C7="#200",8,IF(C7="<200",9)))))))),FALSE) -> 23.25 | P7: =SUMIFS(J:J,B:B,B7,C:C,C7)/COUNTIFS(B:B,B7,C:C,C7) -> 0.5575 | Q7: =SUMIFS(E:E,B:B,B7,C:C,C7)/COUNTIFS(B:B,B7,C:C,C7) -> 3.9625 | R7: =VLOOKUP(B7,'Dry Sieve'!$B$2:$K$992,IF(C7="#5",2,IF(C7="#10",3,IF(C7="#18",4,IF(C7="#35",5,IF(C7="#60",6,IF(C7="#120",7,IF(C7="#200",8,IF(C7="<200",9)))))))),FALSE) -> 23.25 | S7: =VLOOKUP(B7,'Dry Sieve'!$B$2:$K$992,10,FALSE) -> 123.48 | T7: 0.16179838 | U7: 0.047292481 | V7: =V5 -> 0.2688883
A8: =VLOOKUP(B7,'Sample ID by Horizon'!A:B,2,FALSE) -> 42499 | B8: X11.208.C1 | C8: #10 | D8: B | E8: 3.91 | F8: 1.74 | G8: 3.43 | H8: 1.69 | I8: 2.58 | J8: 0.84 | K8: 21.73913 | L8: =L7 -> 3.9625 | M8: =M7 -> 0.5575 | N8: =N7 -> 34.100811 | O8: =VLOOKUP(B8,'Dry Sieve'!$B$2:$K$992,IF(C8="#5",2,IF(C8="#10",3,IF(C8="#18",4,IF(C8="#35",5,IF(C8="#60",6,IF(C8="#120",7,IF(C8="#200",8,IF(C8="<200",9)))))))),FALSE) -> 23.25 | P8: =SUMIFS(J:J,B:B,B8,C:C,C8)/COUNTIFS(B:B,B8,C:C,C8) -> 0.5575 | Q8: =SUMIFS(E:E,B:B,B8,C:C,C8)/COUNTIFS(B:B,B8,C:C,C8) -> 3.9625 | R8: =VLOOKUP(B8,'Dry Sieve'!$B$2:$K$992,IF(C8="#5",2,IF(C8="#10",3,IF(C8="#18",4,IF(C8="#35",5,IF(C8="#60",6,IF(C8="#120",7,IF(C8="#200",8,IF(C8="<200",9)))))))),FALSE) -> 23.25 | S8: =VLOOKUP(B8,'Dry Sieve'!$B$2:$K$992,10,FALSE) -> 123.48 | T8: 0.16179838 | U8: 0.047292481 | V8: =V7 -> 0.2688883
A9: =VLOOKUP(B8,'Sample ID by Horizon'!A:B,2,FALSE) -> 42499 | B9: X11.208.C1 | C9: #10 | D9: A1 | E9: 3.98 | F9: 1.72 | G9: 4.02 | H9: 2.3 | I9: 2.09 | J9: 0.37 | K9: 48.492462 | L9: =L7 -> 3.9625 | M9: =M7 -> 0.5575 | N9: =N7 -> 34.100811 | O9: =VLOOKUP(B9,'Dry Sieve'!$B$2:$K$992,IF(C9="#5",2,IF(C9="#10",3,IF(C9="#18",4,IF(C9="#35",5,IF(C9="#60",6,IF(C9="#120",7,IF(C9="#200",8,IF(C9="<200",9)))))))),FALSE) -> 23.25 | P9: =SUMIFS(J:J,B:B,B9,C:C,C9)/COUNTIFS(B:B,B9,C:C,C9) -> 0.5575 | Q9: =SUMIFS(E:E,B:B,B9,C:C,C9)/COUNTIFS(B:B,B9,C:C,C9) -> 3.9625 | R9: =VLOOKUP(B9,'Dry Sieve'!$B$2:$K$992,IF(C9="#5",2,IF(C9="#10",3,IF(C9="#18",4,IF(C9="#35",5,IF(C9="#60",6,IF(C9="#120",7,IF(C9="#200",8,IF(C9="<200",9)))))))),FALSE) -> 23.25 | S9: =VLOOKUP(B9,'Dry Sieve'!$B$2:$K$992,10,FALSE) -> 123.48 | T9: 0.16179838 | U9: 0.047292481 | V9: =V7 -> 0.2688883
A10: =VLOOKUP(B9,'Sample ID by Horizon'!A:B,2,FALSE) -> 42499 | B10: X11.208.C1 | C10: #10 | D10: B1 | E10: 4.03 | F10: 1.73 | G10: 3.72 | H10: 1.99 | I10: 2.13 | J10: 0.4 | K10: 39.454094 | L10: =L7 -> 3.9625 | M10: =M7 -> 0.5575 | N10: =N7 -> 34.100811 | O10: =VLOOKUP(B10,'Dry Sieve'!$B$2:$K$992,IF(C10="#5",2,IF(C10="#10",3,IF(C10="#18",4,IF(C10="#35",5,IF(C10="#60",6,IF(C10="#120",7,IF(C10="#200",8,IF(C10="<200",9)))))))),FALSE) -> 23.25 | P10: =SUMIFS(J:J,B:B,B10,C:C,C10)/COUNTIFS(B:B,B10,C:C,C10) -> 0.5575 | Q10: =SUMIFS(E:E,B:B,B10,C:C,C10)/COUNTIFS(B:B,B10,C:C,C10) -> 3.9625 | R10: =VLOOKUP(B10,'Dry Sieve'!$B$2:$K$992,IF(C10="#5",2,IF(C10="#10",3,IF(C10="#18",4,IF(C10="#35",5,IF(C10="#60",6,IF(C10="#120",7,IF(C10="#200",8,IF(C10="<200",9)))))))),FALSE) -> 23.25 | S10: =VLOOKUP(B10,'Dry Sieve'!$B$2:$K$992,10,FALSE) -> 123.48 | T10: 0.16179838 | U10: 0.047292481 | V10: =V9 -> 0.2688883
A11: =VLOOKUP(B10,'Sample ID by Horizon'!A:B,2,FALSE) -> 42499 | B11: X11.208.C1 | C11: #18 | D11: A | E11: 2.1 | F11: 1.73 | G11: 3.02 | H11: 1.29 | I11: 2.1 | J11: 0.37 | K11: 43.809524 | L11: 2.08 | M11: =AVERAGE(J11:J14) -> 0.355 | N11: 39.951514 | O11: =VLOOKUP(B11,'Dry Sieve'!$B$2:$K$992,IF(C11="#5",2,IF(C11="#10",3,IF(C11="#18",4,IF(C11="#35",5,IF(C11="#60",6,IF(C11="#120",7,IF(C11="#200",8,IF(C11="<200",9)))))))),FALSE) -> 17.05 | P11: =SUMIFS(J:J,B:B,B11,C:C,C11)/COUNTIFS(B:B,B11,C:C,C11) -> 0.355 | Q11: =SUMIFS(E:E,B:B,B11,C:C,C11)/COUNTIFS(B:B,B11,C:C,C11) -> 2.08 | R11: =VLOOKUP(B11,'Dry Sieve'!$B$2:$K$992,IF(C11="#5",2,IF(C11="#10",3,IF(C11="#18",4,IF(C11="#35",5,IF(C11="#60",6,IF(C11="#120",7,IF(C11="#200",8,IF(C11="<200",9)))))))),FALSE) -> 17.05 | S11: =VLOOKUP(B11,'Dry Sieve'!$B$2:$K$992,10,FALSE) -> 123.48 | T11: 0.11451267 | U11: 0.032678246 | V11: =V9 -> 0.2688883
A12: =VLOOKUP(B11,'Sample ID by Horizon'!A:B,2,FALSE) -> 42499 | B12: X11.208.C1 | C12: #18 | D12: B | E12: 2.04 | F12: 1.74 | G12: 2.83 | H12: 1.09 | I12: 2.03 | J12: 0.29 | K12: 39.215686 | L12: =L11 -> 2.08 | M12: =M11 -> 0.355 | N12: =N11 -> 39.951514 | O12: =VLOOKUP(B12,'Dry Sieve'!$B$2:$K$992,IF(C12="#5",2,IF(C12="#10",3,IF(C12="#18",4,IF(C12="#35",5,IF(C12="#60",6,IF(C12="#120",7,IF(C12="#200",8,IF(C12="<200",9)))))))),FALSE) -> 17.05 | P12: =SUMIFS(J:J,B:B,B12,C:C,C12)/COUNTIFS(B:B,B12,C:C,C12) -> 0.355 | Q12: =SUMIFS(E:E,B:B,B12,C:C,C12)/COUNTIFS(B:B,B12,C:C,C12) -> 2.08 | R12: =VLOOKUP(B12,'Dry Sieve'!$B$2:$K$992,IF(C12="#5",2,IF(C12="#10",3,IF(C12="#18",4,IF(C12="#35",5,IF(C12="#60",6,IF(C12="#120",7,IF(C12="#200",8,IF(C12="<200",9)))))))),FALSE) -> 17.05 | S12: =VLOOKUP(B12,'Dry Sieve'!$B$2:$K$992,10,FALSE) -> 123.48 | T12: 0.11451267 | U12: 0.032678246 | V12: =V11 -> 0.2688883
A13: =VLOOKUP(B12,'Sample ID by Horizon'!A:B,2,FALSE) -> 42499 | B13: X11.208.C1 | C13: #18 | D13: A1 | E13: 2.15 | F13: 1.73 | G13: 3.06 | H13: 1.33 | I13: 2.14 | J13: 0.41 | K13: 42.790698 | L13: =L11 -> 2.08 | M13: =M11 -> 0.355 | N13: =N11 -> 39.951514 | O13: =VLOOKUP(B13,'Dry Sieve'!$B$2:$K$992,IF(C13="#5",2,IF(C13="#10",3,IF(C13="#18",4,IF(C13="#35",5,IF(C13="#60",6,IF(C13="#120",7,IF(C13="#200",8,IF(C13="<200",9)))))))),FALSE) -> 17.05 | P13: =SUMIFS(J:J,B:B,B13,C:C,C13)/COUNTIFS(B:B,B13,C:C,C13) -> 0.355 | Q13: =SUMIFS(E:E,B:B,B13,C:C,C13)/COUNTIFS(B:B,B13,C:C,C13) -> 2.08 | R13: =VLOOKUP(B13,'Dry Sieve'!$B$2:$K$992,IF(C13="#5",2,IF(C13="#10",3,IF(C13="#18",4,IF(C13="#35",5,IF(C13="#60",6,IF(C13="#120",7,IF(C13="#200",8,IF(C13="<200",9)))))))),FALSE) -> 17.05 | S13: =VLOOKUP(B13,'Dry Sieve'!$B$2:$K$992,10,FALSE) -> 123.48 | T13: 0.11451267 | U13: 0.032678246 | V13: =V11 -> 0.2688883
A14: =VLOOKUP(B13,'Sample ID by Horizon'!A:B,2,FALSE) -> 42499 | B14: X11.208.C1 | C14: #18 | D14: B1 | E14: 2.03 | F14: 1.74 | G14: 2.78 | H14: 1.04 | I14: 2.09 | J14: 0.35 | K14: 33.990148 | L14: =L11 -> 2.08 | M14: =M11 -> 0.355 | N14: =N11 -> 39.951514 | O14: =VLOOKUP(B14,'Dry Sieve'!$B$2:$K$992,IF(C14="#5",2,IF(C14="#10",3,IF(C14="#18",4,IF(C14="#35",5,IF(C14="#60",6,IF(C14="#120",7,IF(C14="#200",8,IF(C14="<200",9)))))))),FALSE) -> 17.05 | P14: =SUMIFS(J:J,B:B,B14,C:C,C14)/COUNTIFS(B:B,B14,C:C,C14) -> 0.355 | Q14: =SUMIFS(E:E,B:B,B14,C:C,C14)/COUNTIFS(B:B,B14,C:C,C14) -> 2.08 | R14: =VLOOKUP(B14,'Dry Sieve'!$B$2:$K$992,IF(C14="#5",2,IF(C14="#10",3,IF(C14="#18",4,IF(C14="#35",5,IF(C14="#60",6,IF(C14="#120",7,IF(C14="#200",8,IF(C14="<200",9)))))))),FALSE) -> 17.05 | S14: =VLOOKUP(B14,'Dry Sieve'!$B$2:$K$992,10,FALSE) -> 123.48 | T14: 0.11451267 | U14: 0.032678246 | V14: =V13 -> 0.2688883
A15: =VLOOKUP(B14,'Sample ID by Horizon'!A:B,2,FALSE) -> 42499 | B15: X11.208.C1 | C15: #35 | D15: A | E15: 2.01 | F15: 1.74 | G15: 3.28 | H15: 1.54 | I15: 2.31 | J15: 0.57 | K15: 48.258706 | L15: 2.055 | M15: =AVERAGE(J15:J18) -> 0.5175 | N15: 48.164038 | O15: =VLOOKUP(B15,'Dry Sieve'!$B$2:$K$992,IF(C15="#5",2,IF(C15="#10",3,IF(C15="#18",4,IF(C15="#35",5,IF(C15="#60",6,IF(C15="#120",7,IF(C15="#200",8,IF(C15="<200",9)))))))),FALSE) -> 11.43 | P15: =SUMIFS(J:J,B:B,B15,C:C,C15)/COUNTIFS(B:B,B15,C:C,C15) -> 0.5175 | Q15: =SUMIFS(E:E,B:B,B15,C:C,C15)/COUNTIFS(B:B,B15,C:C,C15) -> 2.055 | R15: =VLOOKUP(B15,'Dry Sieve'!$B$2:$K$992,IF(C15="#5",2,IF(C15="#10",3,IF(C15="#18",4,IF(C15="#35",5,IF(C15="#60",6,IF(C15="#120",7,IF(C15="#200",8,IF(C15="<200",9)))))))),FALSE) -> 11.43 | S15: =VLOOKUP(B15,'Dry Sieve'!$B$2:$K$992,10,FALSE) -> 123.48 | T15: 0.069255283 | U15: 0.019060652 | V15: =V13 -> 0.2688883
A16: =VLOOKUP(B15,'Sample ID by Horizon'!A:B,2,FALSE) -> 42499 | B16: X11.208.C1 | C16: #35 | D16: B | E16: 2.11 | F16: 1.73 | G16: 3.2 | H16: 1.47 | I16: 2.14 | J16: 0.41 | K16: 50.236967 | L16: =L15 -> 2.055 | M16: =M15 -> 0.5175 | N16: =N15 -> 48.164038 | O16: =VLOOKUP(B16,'Dry Sieve'!$B$2:$K$992,IF(C16="#5",2,IF(C16="#10",3,IF(C16="#18",4,IF(C16="#35",5,IF(C16="#60",6,IF(C16="#120",7,IF(C16="#200",8,IF(C16="<200",9)))))))),FALSE) -> 11.43 | P16: =SUMIFS(J:J,B:B,B16,C:C,C16)/COUNTIFS(B:B,B16,C:C,C16) -> 0.5175 | Q16: =SUMIFS(E:E,B:B,B16,C:C,C16)/COUNTIFS(B:B,B16,C:C,C16) -> 2.055 | R16: =VLOOKUP(B16,'Dry Sieve'!$B$2:$K$992,IF(C16="#5",2,IF(C16="#10",3,IF(C16="#18",4,IF(C16="#35",5,IF(C16="#60",6,IF(C16="#120",7,IF(C16="#200",8,IF(C16="<200",9)))))))),FALSE) -> 11.43 | S16: =VLOOKUP(B16,'Dry Sieve'!$B$2:$K$992,10,FALSE) -> 123.48 | T16: 0.069255283 | U16: 0.019060652 | V16: =V15 -> 0.2688883
A17: =VLOOKUP(B16,'Sample ID by Horizon'!A:B,2,FALSE) -> 42499 | B17: X11.208.C1 | C17: #35 | D17: A1 | E17: 2.06 | F17: 1.73 | G17: 3.27 | H17: 1.54 | I17: 2.33 | J17: 0.6 | K17: 45.631068 | L17: =L15 -> 2.055 | M17: =M15 -> 0.5175 | N17: =N15 -> 48.164038 | O17: =VLOOKUP(B17,'Dry Sieve'!$B$2:$K$992,IF(C17="#5",2,IF(C17="#10",3,IF(C17="#18",4,IF(C17="#35",5,IF(C17="#60",6,IF(C17="#120",7,IF(C17="#200",8,IF(C17="<200",9)))))))),FALSE) -> 11.43 | P17: =SUMIFS(J:J,B:B,B17,C:C,C17)/COUNTIFS(B:B,B17,C:C,C17) -> 0.5175 | Q17: =SUMIFS(E:E,B:B,B17,C:C,C17)/COUNTIFS(B:B,B17,C:C,C17) -> 2.055 | R17: =VLOOKUP(B17,'Dry Sieve'!$B$2:$K$992,IF(C17="#5",2,IF(C17="#10",3,IF(C17="#18",4,IF(C17="#35",5,IF(C17="#60",6,IF(C17="#120",7,IF(C17="#200",8,IF(C17="<200",9)))))))),FALSE) -> 11.43 | S17: =VLOOKUP(B17,'Dry Sieve'!$B$2:$K$992,10,FALSE) -> 123.48 | T17: 0.069255283 | U17: 0.019060652 | V17: =V15 -> 0.2688883
A18: =VLOOKUP(B17,'Sample ID by Horizon'!A:B,2,FALSE) -> 42499 | B18: X11.208.C1 | C18: #35 | D18: B1 | E18: 2.04 | F18: 1.74 | G18: 3.22 | H18: 1.48 | I18: 2.23 | J18: 0.49 | K18: 48.529412 | L18: =L15 -> 2.055 | M18: =M15 -> 0.5175 | N18: =N15 -> 48.164038 | O18: =VLOOKUP(B18,'Dry Sieve'!$B$2:$K$992,IF(C18="#5",2,IF(C18="#10",3,IF(C18="#18",4,IF(C18="#35",5,IF(C18="#60",6,IF(C18="#120",7,IF(C18="#200",8,IF(C18="<200",9)))))))),FALSE) -> 11.43 | P18: =SUMIFS(J:J,B:B,B18,C:C,C18)/COUNTIFS(B:B,B18,C:C,C18) -> 0.5175 | Q18: =SUMIFS(E:E,B:B,B18,C:C,C18)/COUNTIFS(B:B,B18,C:C,C18) -> 2.055 | R18: =VLOOKUP(B18,'Dry Sieve'!$B$2:$K$992,IF(C18="#5",2,IF(C18="#10",3,IF(C18="#18",4,IF(C18="#35",5,IF(C18="#60",6,IF(C18="#120",7,IF(C18="#200",8,IF(C18="<200",9)))))))),FALSE) -> 11.43 | S18: =VLOOKUP(B18,'Dry Sieve'!$B$2:$K$992,10,FALSE) -> 123.48 | T18: 0.069255283 | U18: 0.019060652 | V18: =V17 -> 0.2688883
A19: =VLOOKUP(B18,'Sample ID by Horizon'!A:B,2,FALSE) -> 42499 | B19: X11.208.C1 | C19: #60 | D19: A | E19: 1.05 | F19: 1.73 | G19: 2.67 | H19: 0.94 | I19: 1.99 | J19: 0.26 | K19: 64.761905 | L19: 1.05 | M19: =AVERAGE(J19:J22) -> 0.2875 | N19: 61.45894 | O19: =VLOOKUP(B19,'Dry Sieve'!$B$2:$K$992,IF(C19="#5",2,IF(C19="#10",3,IF(C19="#18",4,IF(C19="#35",5,IF(C19="#60",6,IF(C19="#120",7,IF(C19="#200",8,IF(C19="<200",9)))))))),FALSE) -> 6.6 | P19: =SUMIFS(J:J,B:B,B19,C:C,C19)/COUNTIFS(B:B,B19,C:C,C19) -> 0.2875 | Q19: =SUMIFS(E:E,B:B,B19,C:C,C19)/COUNTIFS(B:B,B19,C:C,C19) -> 1.05 | R19: =VLOOKUP(B19,'Dry Sieve'!$B$2:$K$992,IF(C19="#5",2,IF(C19="#10",3,IF(C19="#18",4,IF(C19="#35",5,IF(C19="#60",6,IF(C19="#120",7,IF(C19="#200",8,IF(C19="<200",9)))))))),FALSE) -> 6.6 | S19: =VLOOKUP(B19,'Dry Sieve'!$B$2:$K$992,10,FALSE) -> 123.48 | T19: 0.038814846 | U19: 0.010223654 | V19: =V17 -> 0.2688883
A20: =VLOOKUP(B19,'Sample ID by Horizon'!A:B,2,FALSE) -> 42499 | B20: X11.208.C1 | C20: #60 | D20: B | E20: 1.03 | F20: 1.73 | G20: 2.61 | H20: 0.88 | I20: 2.01 | J20: 0.28 | K20: 58.252427 | L20: =L19 -> 1.05 | M20: =M19 -> 0.2875 | N20: =N19 -> 61.45894 | O20: =VLOOKUP(B20,'Dry Sieve'!$B$2:$K$992,IF(C20="#5",2,IF(C20="#10",3,IF(C20="#18",4,IF(C20="#35",5,IF(C20="#60",6,IF(C20="#120",7,IF(C20="#200",8,IF(C20="<200",9)))))))),FALSE) -> 6.6 | P20: =SUMIFS(J:J,B:B,B20,C:C,C20)/COUNTIFS(B:B,B20,C:C,C20) -> 0.2875 | Q20: =SUMIFS(E:E,B:B,B20,C:C,C20)/COUNTIFS(B:B,B20,C:C,C20) -> 1.05 | R20: =VLOOKUP(B20,'Dry Sieve'!$B$2:$K$992,IF(C20="#5",2,IF(C20="#10",3,IF(C20="#18",4,IF(C20="#35",5,IF(C20="#60",6,IF(C20="#120",7,IF(C20="#200",8,IF(C20="<200",9)))))))),FALSE) -> 6.6 | S20: =VLOOKUP(B20,'Dry Sieve'!$B$2:$K$992,10,FALSE) -> 123.48 | T20: 0.038814846 | U20: 0.010223654 | V20: =V19 -> 0.2688883
A21: =VLOOKUP(B20,'Sample ID by Horizon'!A:B,2,FALSE) -> 42499 | B21: X11.208.C1 | C21: #60 | D21: A1 | E21: 1 | F21: 1.73 | G21: 2.66 | H21: 0.93 | I21: 2.03 | J21: 0.3 | K21: 63 | L21: =L19 -> 1.05 | M21: =M19 -> 0.2875 | N21: =N19 -> 61.45894 | O21: =VLOOKUP(B21,'Dry Sieve'!$B$2:$K$992,IF(C21="#5",2,IF(C21="#10",3,IF(C21="#18",4,IF(C21="#35",5,IF(C21="#60",6,IF(C21="#120",7,IF(C21="#200",8,IF(C21="<200",9)))))))),FALSE) -> 6.6 | P21: =SUMIFS(J:J,B:B,B21,C:C,C21)/COUNTIFS(B:B,B21,C:C,C21) -> 0.2875 | Q21: =SUMIFS(E:E,B:B,B21,C:C,C21)/COUNTIFS(B:B,B21,C:C,C21) -> 1.05 | R21: =VLOOKUP(B21,'Dry Sieve'!$B$2:$K$992,IF(C21="#5",2,IF(C21="#10",3,IF(C21="#18",4,IF(C21="#35",5,IF(C21="#60",6,IF(C21="#120",7,IF(C21="#200",8,IF(C21="<200",9)))))))),FALSE) -> 6.6 | S21: =VLOOKUP(B21,'Dry Sieve'!$B$2:$K$992,10,FALSE) -> 123.48 | T21: 0.038814846 | U21: 0.010223654 | V21: =V19 -> 0.2688883
A22: =VLOOKUP(B21,'Sample ID by Horizon'!A:B,2,FALSE) -> 42499 | B22: X11.208.C1 | C22: #60 | D22: B1 | E22: 1.12 | F22: 1.74 | G22: 2.72 | H22: 0.98 | I22: 2.05 | J22: 0.31 | K22: 59.821429 | L22: =L19 -> 1.05 | M22: =M19 -> 0.2875 | N22: =N19 -> 61.45894 | O22: =VLOOKUP(B22,'Dry Sieve'!$B$2:$K$992,IF(C22="#5",2,IF(C22="#10",3,IF(C22="#18",4,IF(C22="#35",5,IF(C22="#60",6,IF(C22="#120",7,IF(C22="#200",8,IF(C22="<200",9)))))))),FALSE) -> 6.6 | P22: =SUMIFS(J:J,B:B,B22,C:C,C22)/COUNTIFS(B:B,B22,C:C,C22) -> 0.2875 | Q22: =SUMIFS(E:E,B:B,B22,C:C,C22)/COUNTIFS(B:B,B22,C:C,C22) -> 1.05 | R22: =VLOOKUP(B22,'Dry Sieve'!$B$2:$K$992,IF(C22="#5",2,IF(C22="#10",3,IF(C22="#18",4,IF(C22="#35",5,IF(C22="#60",6,IF(C22="#120",7,IF(C22="#200",8,IF(C22="<200",9)))))))),FALSE) -> 6.6 | S22: =VLOOKUP(B22,'Dry Sieve'!$B$2:$K$992,10,FALSE) -> 123.48 | T22: 0.038814846 | U22: 0.010223654 | V22: =V21 -> 0.2688883
A23: =VLOOKUP(B22,'Sample ID by Horizon'!A:B,2,FALSE) -> 42499 | B23: X11.208.C1 | C23: #120 | D23: A | E23: 0.52 | F23: 1.73 | G23: 2.23 | H23: 0.5 | I23: 1.96 | J23: 0.23 | K23: 51.923077 | L23: 0.5275 | M23: =AVERAGE(J23:J26) -> 0.2375 | N23: 52.142128 | O23: =VLOOKUP(B23,'Dry Sieve'!$B$2:$K$992,IF(C23="#5",2,IF(C23="#10",3,IF(C23="#18",4,IF(C23="#35",5,IF(C23="#60",6,IF(C23="#120",7,IF(C23="#200",8,IF(C23="<200",9)))))))),FALSE) -> 2.76 | P23: =SUMIFS(J:J,B:B,B23,C:C,C23)/COUNTIFS(B:B,B23,C:C,C23) -> 0.2375 | Q23: =SUMIFS(E:E,B:B,B23,C:C,C23)/COUNTIFS(B:B,B23,C:C,C23) -> 0.5275 | R23: =VLOOKUP(B23,'Dry Sieve'!$B$2:$K$992,IF(C23="#5",2,IF(C23="#10",3,IF(C23="#18",4,IF(C23="#35",5,IF(C23="#60",6,IF(C23="#120",7,IF(C23="#200",8,IF(C23="<200",9)))))))),FALSE) -> 2.76 | S23: =VLOOKUP(B23,'Dry Sieve'!$B$2:$K$992,10,FALSE) -> 123.48 | T23: 0.012288192 | U23: 0.0018306642 | V23: =V21 -> 0.2688883
A24: =VLOOKUP(B23,'Sample ID by Horizon'!A:B,2,FALSE) -> 42499 | B24: X11.208.C1 | C24: #120 | D24: B | E24: 0.54 | F24: 1.73 | G24: 2.25 | H24: 0.52 | I24: 1.94 | J24: 0.21 | K24: 57.407407 | L24: =L23 -> 0.5275 | M24: =M23 -> 0.2375 | N24: =N23 -> 52.142128 | O24: =VLOOKUP(B24,'Dry Sieve'!$B$2:$K$992,IF(C24="#5",2,IF(C24="#10",3,IF(C24="#18",4,IF(C24="#35",5,IF(C24="#60",6,IF(C24="#120",7,IF(C24="#200",8,IF(C24="<200",9)))))))),FALSE) -> 2.76 | P24: =SUMIFS(J:J,B:B,B24,C:C,C24)/COUNTIFS(B:B,B24,C:C,C24) -> 0.2375 | Q24: =SUMIFS(E:E,B:B,B24,C:C,C24)/COUNTIFS(B:B,B24,C:C,C24) -> 0.5275 | R24: =VLOOKUP(B24,'Dry Sieve'!$B$2:$K$992,IF(C24="#5",2,IF(C24="#10",3,IF(C24="#18",4,IF(C24="#35",5,IF(C24="#60",6,IF(C24="#120",7,IF(C24="#200",8,IF(C24="<200",9)))))))),FALSE) -> 2.76 | S24: =VLOOKUP(B24,'Dry Sieve'!$B$2:$K$992,10,FALSE) -> 123.48 | T24: 0.012288192 | U24: 0.0018306642 | V24: =V23 -> 0.2688883
